Workbook
Name pivot_individual_talents_both_data: pivot_data!$A$314:$D$314
Name pivot_individual_talents_both_headers: pivot_data!$A$313:$D$313
Name pivot_individual_talents_dps_data: pivot_data!$A$316:$C$316
Name pivot_individual_talents_dps_headers: pivot_data!$A$315:$C$315
Name pivot_individual_talents_priority_dps_data: pivot_data!$A$318:$C$318
Name pivot_individual_talents_priority_dps_headers: pivot_data!$A$317:$C$317
Name pivot_race_both_data: pivot_data!$A$275:$D$275
Name pivot_race_both_headers: pivot_data!$A$274:$D$274
Name pivot_race_dps_data: pivot_data!$A$278:$C$278
Name pivot_race_dps_headers: pivot_data!$A$277:$C$277
Name pivot_race_priority_dps_data: pivot_data!$A$281:$C$281
Name pivot_race_priority_dps_headers: pivot_data!$A$280:$C$280
Name pivot_stat_profile_both_data: pivot_data!$A$296:$D$296
Name pivot_stat_profile_both_headers: pivot_data!$A$295:$D$295
Name pivot_stat_profile_dps_data: pivot_data!$A$299:$C$299
Name pivot_stat_profile_dps_headers: pivot_data!$A$298:$C$298
Name pivot_stat_profile_priority_dps_data: pivot_data!$A$302:$C$302
Name pivot_stat_profile_priority_dps_headers: pivot_data!$A$301:$C$301
Name pivot_talent_str_both_data: pivot_data!$A$2:$D$90
Name pivot_talent_str_both_headers: pivot_data!$A$1:$D$1
Name pivot_talent_str_dps_data: pivot_data!$A$93:$C$181
Name pivot_talent_str_dps_headers: pivot_data!$A$92:$C$92
Name pivot_talent_str_priority_dps_data: pivot_data!$A$184:$C$272
Name pivot_talent_str_priority_dps_headers: pivot_data!$A$183:$C$183
Name pivot_trinket_both_data: pivot_data!$A$284:$D$285
Name pivot_trinket_both_headers: pivot_data!$A$283:$D$283
Name pivot_trinket_dps_data: pivot_data!$A$288:$C$289
Name pivot_trinket_dps_headers: pivot_data!$A$287:$C$287
Name pivot_trinket_pair_both_data: pivot_data!$A$305:$D$305
Name pivot_trinket_pair_both_headers: pivot_data!$A$304:$D$304
Name pivot_trinket_pair_dps_data: pivot_data!$A$308:$C$308
Name pivot_trinket_pair_dps_headers: pivot_data!$A$307:$C$307
Name pivot_trinket_pair_priority_dps_data: pivot_data!$A$311:$C$311
Name pivot_trinket_pair_priority_dps_headers: pivot_data!$A$310:$C$310
Name pivot_trinket_priority_dps_data: pivot_data!$A$292:$C$293
Name pivot_trinket_priority_dps_headers: pivot_data!$A$291:$C$291

Sheet Data
A1: file | B1: builds | C1: build_id | D1: dps | E1: priority_dps | F1: race | G1: class | H1: spec | I1: range_pct_dps | J1: talent_str | K1: targets | L1: crit | M1: haste | N1: vers | O1: mastery | P1: min_dps | Q1: max_dps | R1: StdDev | S1: trinket_1 | T1: trinket_2
A2: 00_baseline_001 | B2: baseline | C2: baseline | D2: 57840.898 | E2: 57840.898 | F2: Void Elf | G2: Mage | H2: Arcane | I2: 18.097679 | J2: C4DAAAAAAAAAAAAAAAAAAAAAAYGmZZmZmFmZGaGzAAAwAAgAmZmZZZmJWAAYbmZmZmZbx2MzMLjxYMzMGbMzMjBAwAAAAzMzsAAwMAA | K2: 1 | L2: 602 | M2: 1237 | N2: 107 | O2: 519 | P2: 52858.478 | Q2: 63326.338 | R2: 1988.9232 | S2: galactic_gladiators_badge_of_ferocity | T2: galactic_gladiators_insignia_of_alacrity
A3: 00_baseline_001 | B3: baseline | C3: mage_arcane_spellslinger_63 | D3: 50507.896 | E3: 50507.896 | F3: Void Elf | G3: Mage | H3: Arcane | I3: 20.437413 | J3: C4DAAAAAAAAAAAAAAAAAAAAAAYGmZZmZmFmZGaGzAAAwAAAAzMzssMzELAAsNmZmZmtNbzMmtxMjxMzMsxMzMmBAYAAAgZmZWAAYGAA | K3: 1 | L3: 602 | M3: 1237 | N3: 107 | O3: 519 | P3: 44894.086 | Q3: 55216.594 | R3: 1817.7199 | S3: galactic_gladiators_badge_of_ferocity | T3: galactic_gladiators_insignia_of_alacrity
A4: 00_baseline_001 | B4: baseline | C4: mage_arcane_spellslinger_30 | D4: 54813.211 | E4: 54813.211 | F4: Void Elf | G4: Mage | H4: Arcane | I4: 24.688773 | J4: C4DAAAAAAAAAAAAAAAAAAAAAAYGmZZmZmFmZGaGzAAAwAAAAzMzssMzELAAsNmZmZmtNbzMmlZmZMmZmhNmZmxAAYAAAgZmZ2AAYGAA | K4: 1 | L4: 602 | M4: 1237 | N4: 107 | O4: 519 | P4: 49500.706 | Q4: 63033.415 | R4: 2143.1229 | S4: galactic_gladiators_badge_of_ferocity | T4: galactic_gladiators_insignia_of_alacrity
A5: 00_baseline_001 | B5: baseline | C5: mage_arcane_spellslinger_1 | D5: 55493.961 | E5: 55493.961 | F5: Void Elf | G5: Mage | H5: Arcane | I5: 24.3623 | J5: C4DAAAAAAAAAAAAAAAAAAAAAAYGmZZmZmFmZGaGzAAAwAAAAzMzssMzELAAsNmZmZmlFLzMmlZmZMmZmhNmZmxAAYAAAgZmZWAAYGAA | K5: 1 | L5: 602 | M5: 1237 | N5: 107 | O5: 519 | P5: 48604.055 | Q5: 62123.66 | R5: 2068.933 | S5: galactic_gladiators_badge_of_ferocity | T5: galactic_gladiators_insignia_of_alacrity
A6: 00_baseline_001 | B6: baseline | C6: mage_arcane_spellslinger_60 | D6: 47978.918 | E6: 47978.918 | F6: Void Elf | G6: Mage | H6: Arcane | I6: 24.013981 | J6: C4DAAAAAAAAAAAAAAAAAAAAAAYGmZZmZmFmZGaGzAAAwAAAAzMzssMzELAAsNmZmZmlNbzMmtxMjxMzMsxMzMmBAYAAAgZmZ2AAYGAA | K6: 1 | L6: 602 | M6: 1237 | N6: 107 | O6: 519 | P6: 42499.007 | Q6: 54020.655 | R6: 1833.4046 | S6: galactic_gladiators_badge_of_ferocity | T6: galactic_gladiators_insignia_of_alacrity
A7: 00_baseline_001 | B7: baseline | C7: mage_arcane_spellslinger_33 | D7: 55141.163 | E7: 55141.163 | F7: Void Elf | G7: Mage | H7: Arcane | I7: 22.166101 | J7: C4DAAAAAAAAAAAAAAAAAAAAAAYGmZZmZmFmZGaGzAAAwAAAAzMzssMzELAAsNmZmZmlFLzMmlxMjxMzMsxMzMmBAYAAAgZmZWAAYGAA | K7: 1 | L7: 602 | M7: 1237 | N7: 107 | O7: 519 | P7: 49744.236 | Q7: 61966.881 | R7: 2042.2121 | S7: galactic_gladiators_badge_of_ferocity | T7: galactic_gladiators_insignia_of_alacrity
A8: 00_baseline_001 | B8: baseline | C8: mage_arcane_spellslinger_2 | D8: 54127.213 | E8: 54127.213 | F8: Void Elf | G8: Mage | H8: Arcane | I8: 22.228705 | J8: C4DAAAAAAAAAAAAAAAAAAAAAAYGmZZmZmFmZGaGzAAAwAAAAzMzssMzELAAsNmZmZmlFLzMmlZmZMmZmhNmZmxAAYAAAgZmZ2AAYGAA | K8: 1 | L8: 602 | M8: 1237 | N8: 107 | O8: 519 | P8: 48018.358 | Q8: 60050.136 | R8: 2105.0535 | S8: galactic_gladiators_badge_of_ferocity | T8: galactic_gladiators_insignia_of_alacrity
A9: 00_baseline_001 | B9: baseline | C9: mage_arcane_spellslinger_61 | D9: 56178.604 | E9: 56178.604 | F9: Void Elf | G9: Mage | H9: Arcane | I9: 24.166146 | J9: C4DAAAAAAAAAAAAAAAAAAAAAAYGmZZmZmFmZGaGzAAAwAAAAzMzssMzELAAsNmZmZmtNbzMmlxMjxMzMsxMzMmBAYAAAgZmZWAAYGAA | K9: 1 | L9: 602 | M9: 1237 | N9: 107 | O9: 519 | P9: 49656.04 | Q9: 63232.244 | R9: 2169.2295 | S9: galactic_gladiators_badge_of_ferocity | T9: galactic_gladiators_insignia_of_alacrity
A10: 00_baseline_001 | B10: baseline | C10: mage_arcane_spellslinger_32 | D10: 49915.516 | E10: 49915.516 | F10: Void Elf | G10: Mage | H10: Arcane | I10: 20.507225 | J10: C4DAAAAAAAAAAAAAAAAAAAAAAYGmZZmZmFmZGaGzAAAwAAAAzMzssMzELAAsNmZmZmtNbzMmtZmZMmZmhNmZmxAAYAAAgZmZ2AAYGAA | K10: 1 | L10: 602 | M10: 1237 | N10: 107 | O10: 519 | P10: 44847.72 | Q10: 55084.007 | R10: 1799.4913 | S10: galactic_gladiators_badge_of_ferocity | T10: galactic_gladiators_insignia_of_alacrity
A11: 00_baseline_001 | B11: baseline | C11: mage_arcane_spellslinger_3 | D11: 49990.81 | E11: 49990.81 | F11: Void Elf | G11: Mage | H11: Arcane | I11: 21.49581 | J11: C4DAAAAAAAAAAAAAAAAAAAAAAYGmZZmZmFmZGaGzAAAwAAAAzMzssMzELAAsNmZmZmlFLzMmtZmZMmZmhNmZmxAAYAAAgZmZWAAYGAA | K11: 1 | L11: 602 | M11: 1237 | N11: 107 | O11: 519 | P11: 44668.735 | Q11: 55414.665 | R11: 1868.7543 | S11: galactic_gladiators_badge_of_ferocity | T11: galactic_gladiators_insignia_of_alacrity
A12: 00_baseline_001 | B12: baseline | C12: mage_arcane_spellslinger_35 | D12: 48822.088 | E12: 48822.088 | F12: Void Elf | G12: Mage | H12: Arcane | I12: 22.327083 | J12: C4DAAAAAAAAAAAAAAAAAAAAAAYGmZZmZmFmZGaGzAAAwAAAAzMzssMzELAAsNmZmZmlFLzMmtxMjxMzMsxMzMmBAYAAAgZmZWAAYGAA | K12: 1 | L12: 602 | M12: 1237 | N12: 107 | O12: 519 | P12: 43867.694 | Q12: 54768.242 | R12: 1817.7731 | S12: galactic_gladiators_badge_of_ferocity | T12: galactic_gladiators_insignia_of_alacrity
A13: 00_baseline_001 | B13: baseline | C13: mage_arcane_spellslinger_79 | D13: 47736.043 | E13: 47736.043 | F13: Void Elf | G13: Mage | H13: Arcane | I13: 26.441758 | J13: C4DAAAAAAAAAAAAAAAAAAAAAAYGmZZmZmFmZGaGzAAAwAAAAzMzssMzELAAsxMzMzstYbmxsNzMjxMzMsxMzMmBAYAAAgZmZWAAYGAA | K13: 1 | L13: 602 | M13: 1237 | N13: 107 | O13: 519 | P13: 42003.9 | Q13: 54626.149 | R13: 1682.5548 | S13: galactic_gladiators_badge_of_ferocity | T13: galactic_gladiators_insignia_of_alacrity
... A179: 01_baseline_001 | B179: baseline | C179: mage_arcane_spellslinger_88 | D179: 45591.953 | E179: 45591.953 | F179: Void Elf | G179: Mage | H179: Arcane | I179: 19.189682 | J179: C4DAAAAAAAAAAAAAAAAAAAAAAYGmZZmZmFmZGaGzAAAwAAAAzMzssMzELAAsxMzMzstZZmxsNzMjxMzMsxMzMmBAYAAAgZmZ2AAYGAA | K179: 1 | L179: 602 | M179: 1237 | N179: 107 | O179: 519 | P179: 41117.103 | Q179: 49866.054 | R179: 1449.5392 | S179: galactic_gladiators_badge_of_ferocity | T179: galactic_gladiators_insignia_of_alacrity

Sheet Summary
A1: Simulation Report
A2: Source CSV: sim_proc_combined_results.csv
A3: Generated: 2025-12-15 20:58:20
A5: Top 100 builds
A6: talent_str | B6: race | C6: trinket_1 | D6: trinket_2 | E6: changed_talents | F6: crit | G6: haste | H6: vers | I6: mastery | J6: 1 Target DPS | K6: 1 Target Priority | L6: Weighted Avg
A7: C4DAAAAAAAAAAAAAAAAAAAAAAYGmZZmZmFmZGaGzAAAwAAgAmZmZZZmJWAAYbmZmZmZbx2MzMLjxYMzMGbMzMjBAwAAAAzMzsAAwMAA | B7: Void Elf | C7: galactic_gladiators_badge_of_ferocity | D7: galactic_gladiators_insignia_of_alacrity | F7: 602 | G7: 1237 | H7: 107 | I7: 519 | J7: 57803.925 | K7: 57803.925 | L7: 1
A8: C4DAAAAAAAAAAAAAAAAAAAAAAYGmZZmZmFmZGaGzAAAwAAAAzMzssMzELAAsNmZmZmtNLzMmlZmZMmZmhNmZmxAAYAAAgZmZWAAYGAA | B8: Void Elf | C8: galactic_gladiators_badge_of_ferocity | D8: galactic_gladiators_insignia_of_alacrity | F8: 602 | G8: 1237 | H8: 107 | I8: 519 | J8: 56667.27 | K8: 56667.27 | L8: 0.98033602
A9: C4DAAAAAAAAAAAAAAAAAAAAAAYGmZZmZmFmZGaGzAAAwAAAAzMzssMzELAAsNmZmZmtNLzMmlxMjxMzMsxMzMmBAYAAAgZmZWAAYGAA | B9: Void Elf | C9: galactic_gladiators_badge_of_ferocity | D9: galactic_gladiators_insignia_of_alacrity | F9: 602 | G9: 1237 | H9: 107 | I9: 519 | J9: 56608.022 | K9: 56608.022 | L9: 0.97931104
A10: C4DAAAAAAAAAAAAAAAAAAAAAAYGmZZmZmFmZGaGzAAAwAAAAzMzssMzELAAsNmZmZmtFLzMmlZmZMmZmhNmZmxAAYAAAgZmZWAAYGAA | B10: Void Elf | C10: galactic_gladiators_badge_of_ferocity | D10: galactic_gladiators_insignia_of_alacrity | F10: 602 | G10: 1237 | H10: 107 | I10: 519 | J10: 56579.38 | K10: 56579.38 | L10: 0.97881554
A11: C4DAAAAAAAAAAAAAAAAAAAAAAYGmZZmZmFmZGaGzAAAwAAAAzMzssMzELAAsNmZmZmtFLzMmlxMjxMzMsxMzMmBAYAAAgZmZWAAYGAA | B11: Void Elf | C11: galactic_gladiators_badge_of_ferocity | D11: galactic_gladiators_insignia_of_alacrity | F11: 602 | G11: 1237 | H11: 107 | I11: 519 | J11: 56549.956 | K11: 56549.956 | L11: 0.9783065
A12: C4DAAAAAAAAAAAAAAAAAAAAAAYGmZZmZmFmZGaGzAAAwAAAAzMzssMzELAAsxMzMzstZZmxsMzMjxMzMsxMzMmBAYAAAgZmZWAAYGAA | B12: Void Elf | C12: galactic_gladiators_badge_of_ferocity | D12: galactic_gladiators_insignia_of_alacrity | F12: 602 | G12: 1237 | H12: 107 | I12: 519 | J12: 56277.87 | K12: 56277.87 | L12: 0.97359945
A13: C4DAAAAAAAAAAAAAAAAAAAAAAYGmZZmZmFmZGaGzAAAwAAAAzMzssMzELAAsxMzMzstYZmxsMzMjxMzMsxMzMmBAYAAAgZmZWAAYGAA | B13: Void Elf | C13: galactic_gladiators_badge_of_ferocity | D13: galactic_gladiators_insignia_of_alacrity | F13: 602 | G13: 1237 | H13: 107 | I13: 519 | J13: 56218.84 | K13: 56218.84 | L13: 0.97257823
A14: C4DAAAAAAAAAAAAAAAAAAAAAAYGmZZmZmFmZGaGzAAAwAAAAzMzssMzELAAsNmZmZmtFbzMmlZmZMmZmhNmZmxAAYAAAgZmZWAAYGAA | B14: Void Elf | C14: galactic_gladiators_badge_of_ferocity | D14: galactic_gladiators_insignia_of_alacrity | F14: 602 | G14: 1237 | H14: 107 | I14: 519 | J14: 56113.468 | K14: 56113.468 | L14: 0.97075532
A15: C4DAAAAAAAAAAAAAAAAAAAAAAYGmZZmZmFmZGaGzAAAwAAAAzMzssMzELAAsNmZmZmtNbzMmlxMjxMzMsxMzMmBAYAAAgZmZWAAYGAA | B15: Void Elf | C15: galactic_gladiators_badge_of_ferocity | D15: galactic_gladiators_insignia_of_alacrity | F15: 602 | G15: 1237 | H15: 107 | I15: 519 | J15: 56112.466 | K15: 56112.466 | L15: 0.97073798
A16: C4DAAAAAAAAAAAAAAAAAAAAAAYGmZZmZmFmZGaGzAAAwAAAAzMzssMzELAAsNmZmZmtNbzMmlZmZMmZmhNmZmxAAYAAAgZmZWAAYGAA | B16: Void Elf | C16: galactic_gladiators_badge_of_ferocity | D16: galactic_gladiators_insignia_of_alacrity | F16: 602 | G16: 1237 | H16: 107 | I16: 519 | J16: 56065.196 | K16: 56065.196 | L16: 0.96992022
A17: C4DAAAAAAAAAAAAAAAAAAAAAAYGmZZmZmFmZGaGzAAAwAAAAzMzssMzELAAsxMzMzstYbmxsMzMjxMzMsxMzMmBAYAAAgZmZWAAYGAA | B17: Void Elf | C17: galactic_gladiators_badge_of_ferocity | D17: galactic_gladiators_insignia_of_alacrity | F17: 602 | G17: 1237 | H17: 107 | I17: 519 | J17: 56032.094 | K17: 56032.094 | L17: 0.96934756
A18: C4DAAAAAAAAAAAAAAAAAAAAAAYGmZZmZmFmZGaGzAAAwAAAAzMzssMzELAAsNmZmZmtFbzMmlxMjxMzMsxMzMmBAYAAAgZmZWAAYGAA | B18: Void Elf | C18: galactic_gladiators_badge_of_ferocity | D18: galactic_gladiators_insignia_of_alacrity | F18: 602 | G18: 1237 | H18: 107 | I18: 519 | J18: 56012.595 | K18: 56012.595 | L18: 0.96901023
... A95: C4DAAAAAAAAAAAAAAAAAAAAAAYGmZZmZmFmZGaGzAAAwAAAAzMzssMzELAAsxMzMzssZZmxsNzMjxMzMsxMzMmBAYAAAgZmZ2AAYGAA | B95: Void Elf | C95: galactic_gladiators_badge_of_ferocity | D95: galactic_gladiators_insignia_of_alacrity | F95: 602 | G95: 1237 | H95: 107 | I95: 519 | J95: 45055.819 | K95: 45055.819 | L95: 0.77945951

Sheet pivot_data
A1: label | B1: 1 Target DPS | C1: 1 Target Priority | D1: weighted_avg
A2: C4DAAAAAAAAAAAAAAAAAAAAAAYGmZZmZmFmZGaGzAAAwAAgAmZmZZZmJWAAYbmZmZmZbx2MzMLjxYMzMGbMzMjBAwAAAAzMzsAAwMAA | B2: 57803.925 | C2: 57803.925 | D2: 1
A3: C4DAAAAAAAAAAAAAAAAAAAAAAYGmZZmZmFmZGaGzAAAwAAAAzMzssMzELAAsNmZmZmtNLzMmlZmZMmZmhNmZmxAAYAAAgZmZWAAYGAA | B3: 56667.27 | C3: 56667.27 | D3: 0.98033602
A4: C4DAAAAAAAAAAAAAAAAAAAAAAYGmZZmZmFmZGaGzAAAwAAAAzMzssMzELAAsNmZmZmtNLzMmlxMjxMzMsxMzMmBAYAAAgZmZWAAYGAA | B4: 56608.022 | C4: 56608.022 | D4: 0.97931104
A5: C4DAAAAAAAAAAAAAAAAAAAAAAYGmZZmZmFmZGaGzAAAwAAAAzMzssMzELAAsNmZmZmtFLzMmlZmZMmZmhNmZmxAAYAAAgZmZWAAYGAA | B5: 56579.38 | C5: 56579.38 | D5: 0.97881554
A6: C4DAAAAAAAAAAAAAAAAAAAAAAYGmZZmZmFmZGaGzAAAwAAAAzMzssMzELAAsNmZmZmtFLzMmlxMjxMzMsxMzMmBAYAAAgZmZWAAYGAA | B6: 56549.956 | C6: 56549.956 | D6: 0.9783065
A7: C4DAAAAAAAAAAAAAAAAAAAAAAYGmZZmZmFmZGaGzAAAwAAAAzMzssMzELAAsxMzMzstZZmxsMzMjxMzMsxMzMmBAYAAAgZmZWAAYGAA | B7: 56277.87 | C7: 56277.87 | D7: 0.97359945
A8: C4DAAAAAAAAAAAAAAAAAAAAAAYGmZZmZmFmZGaGzAAAwAAAAzMzssMzELAAsxMzMzstYZmxsMzMjxMzMsxMzMmBAYAAAgZmZWAAYGAA | B8: 56218.84 | C8: 56218.84 | D8: 0.97257823
A9: C4DAAAAAAAAAAAAAAAAAAAAAAYGmZZmZmFmZGaGzAAAwAAAAzMzssMzELAAsNmZmZmtFbzMmlZmZMmZmhNmZmxAAYAAAgZmZWAAYGAA | B9: 56113.468 | C9: 56113.468 | D9: 0.97075532
A10: C4DAAAAAAAAAAAAAAAAAAAAAAYGmZZmZmFmZGaGzAAAwAAAAzMzssMzELAAsNmZmZmtNbzMmlxMjxMzMsxMzMmBAYAAAgZmZWAAYGAA | B10: 56112.466 | C10: 56112.466 | D10: 0.97073798
A11: C4DAAAAAAAAAAAAAAAAAAAAAAYGmZZmZmFmZGaGzAAAwAAAAzMzssMzELAAsNmZmZmtNbzMmlZmZMmZmhNmZmxAAYAAAgZmZWAAYGAA | B11: 56065.196 | C11: 56065.196 | D11: 0.96992022
A12: C4DAAAAAAAAAAAAAAAAAAAAAAYGmZZmZmFmZGaGzAAAwAAAAzMzssMzELAAsxMzMzstYbmxsMzMjxMzMsxMzMmBAYAAAgZmZWAAYGAA | B12: 56032.094 | C12: 56032.094 | D12: 0.96934756
A13: C4DAAAAAAAAAAAAAAAAAAAAAAYGmZZmZmFmZGaGzAAAwAAAAzMzssMzELAAsNmZmZmtFbzMmlxMjxMzMsxMzMmBAYAAAgZmZWAAYGAA | B13: 56012.595 | C13: 56012.595 | D13: 0.96901023
... A90: C4DAAAAAAAAAAAAAAAAAAAAAAYGmZZmZmFmZGaGzAAAwAAAAzMzssMzELAAsxMzMzssZZmxsNzMjxMzMsxMzMmBAYAAAgZmZ2AAYGAA | B90: 45055.819 | C90: 45055.819 | D90: 0.77945951
A92: label | B92: 1 Target DPS | C92: weighted_avg
A93: C4DAAAAAAAAAAAAAAAAAAAAAAYGmZZmZmFmZGaGzAAAwAAgAmZmZZZmJWAAYbmZmZmZbx2MzMLjxYMzMGbMzMjBAwAAAAzMzsAAwMAA | B93: 57803.925 | C93: 1
A94: C4DAAAAAAAAAAAAAAAAAAAAAAYGmZZmZmFmZGaGzAAAwAAAAzMzssMzELAAsNmZmZmtNLzMmlZmZMmZmhNmZmxAAYAAAgZmZWAAYGAA | B94: 56667.27 | C94: 0.98033602
A95: C4DAAAAAAAAAAAAAAAAAAAAAAYGmZZmZmFmZGaGzAAAwAAAAzMzssMzELAAsNmZmZmtNLzMmlxMjxMzMsxMzMmBAYAAAgZmZWAAYGAA | B95: 56608.022 | C95: 0.97931104
A96: C4DAAAAAAAAAAAAAAAAAAAAAAYGmZZmZmFmZGaGzAAAwAAAAzMzssMzELAAsNmZmZmtFLzMmlZmZMmZmhNmZmxAAYAAAgZmZWAAYGAA | B96: 56579.38 | C96: 0.97881554
A97: C4DAAAAAAAAAAAAAAAAAAAAAAYGmZZmZmFmZGaGzAAAwAAAAzMzssMzELAAsNmZmZmtFLzMmlxMjxMzMsxMzMmBAYAAAgZmZWAAYGAA | B97: 56549.956 | C97: 0.9783065
A98: C4DAAAAAAAAAAAAAAAAAAAAAAYGmZZmZmFmZGaGzAAAwAAAAzMzssMzELAAsxMzMzstZZmxsMzMjxMzMsxMzMmBAYAAAgZmZWAAYGAA | B98: 56277.87 | C98: 0.97359945
A99: C4DAAAAAAAAAAAAAAAAAAAAAAYGmZZmZmFmZGaGzAAAwAAAAzMzssMzELAAsxMzMzstYZmxsMzMjxMzMsxMzMmBAYAAAgZmZWAAYGAA | B99: 56218.84 | C99: 0.97257823
A100: C4DAAAAAAAAAAAAAAAAAAAAAAYGmZZmZmFmZGaGzAAAwAAAAzMzssMzELAAsNmZmZmtFbzMmlZmZMmZmhNmZmxAAYAAAgZmZWAAYGAA | B100: 56113.468 | C100: 0.97075532
A101: C4DAAAAAAAAAAAAAAAAAAAAAAYGmZZmZmFmZGaGzAAAwAAAAzMzssMzELAAsNmZmZmtNbzMmlxMjxMzMsxMzMmBAYAAAgZmZWAAYGAA | B101: 56112.466 | C101: 0.97073798
A102: C4DAAAAAAAAAAAAAAAAAAAAAAYGmZZmZmFmZGaGzAAAwAAAAzMzssMzELAAsNmZmZmtNbzMmlZmZMmZmhNmZmxAAYAAAgZmZWAAYGAA | B102: 56065.196 | C102: 0.96992022
A103: C4DAAAAAAAAAAAAAAAAAAAAAAYGmZZmZmFmZGaGzAAAwAAAAzMzssMzELAAsxMzMzstYbmxsMzMjxMzMsxMzMmBAYAAAgZmZWAAYGAA | B103: 56032.094 | C103: 0.96934756
A104: C4DAAAAAAAAAAAAAAAAAAAAAAYGmZZmZmFmZGaGzAAAwAAAAzMzssMzELAAsNmZmZmtFbzMmlxMjxMzMsxMzMmBAYAAAgZmZWAAYGAA | B104: 56012.595 | C104: 0.96901023
... A181: C4DAAAAAAAAAAAAAAAAAAAAAAYGmZZmZmFmZGaGzAAAwAAAAzMzssMzELAAsxMzMzssZZmxsNzMjxMzMsxMzMmBAYAAAgZmZ2AAYGAA | B181: 45055.819 | C181: 0.77945951
A183: label | B183: 1 Target Priority | C183: weighted_avg
A184: C4DAAAAAAAAAAAAAAAAAAAAAAYGmZZmZmFmZGaGzAAAwAAgAmZmZZZmJWAAYbmZmZmZbx2MzMLjxYMzMGbMzMjBAwAAAAzMzsAAwMAA | B184: 57803.925 | C184: 1
A185: C4DAAAAAAAAAAAAAAAAAAAAAAYGmZZmZmFmZGaGzAAAwAAAAzMzssMzELAAsNmZmZmtNLzMmlZmZMmZmhNmZmxAAYAAAgZmZWAAYGAA | B185: 56667.27 | C185: 0.98033602
A186: C4DAAAAAAAAAAAAAAAAAAAAAAYGmZZmZmFmZGaGzAAAwAAAAzMzssMzELAAsNmZmZmtNLzMmlxMjxMzMsxMzMmBAYAAAgZmZWAAYGAA | B186: 56608.022 | C186: 0.97931104
A187: C4DAAAAAAAAAAAAAAAAAAAAAAYGmZZmZmFmZGaGzAAAwAAAAzMzssMzELAAsNmZmZmtFLzMmlZmZMmZmhNmZmxAAYAAAgZmZWAAYGAA | B187: 56579.38 | C187: 0.97881554
A188: C4DAAAAAAAAAAAAAAAAAAAAAAYGmZZmZmFmZGaGzAAAwAAAAzMzssMzELAAsNmZmZmtFLzMmlxMjxMzMsxMzMmBAYAAAgZmZWAAYGAA | B188: 56549.956 | C188: 0.9783065
A189: C4DAAAAAAAAAAAAAAAAAAAAAAYGmZZmZmFmZGaGzAAAwAAAAzMzssMzELAAsxMzMzstZZmxsMzMjxMzMsxMzMmBAYAAAgZmZWAAYGAA | B189: 56277.87 | C189: 0.97359945
A190: C4DAAAAAAAAAAAAAAAAAAAAAAYGmZZmZmFmZGaGzAAAwAAAAzMzssMzELAAsxMzMzstYZmxsMzMjxMzMsxMzMmBAYAAAgZmZWAAYGAA | B190: 56218.84 | C190: 0.97257823
A191: C4DAAAAAAAAAAAAAAAAAAAAAAYGmZZmZmFmZGaGzAAAwAAAAzMzssMzELAAsNmZmZmtFbzMmlZmZMmZmhNmZmxAAYAAAgZmZWAAYGAA | B191: 56113.468 | C191: 0.97075532
A192: C4DAAAAAAAAAAAAAAAAAAAAAAYGmZZmZmFmZGaGzAAAwAAAAzMzssMzELAAsNmZmZmtNbzMmlxMjxMzMsxMzMmBAYAAAgZmZWAAYGAA | B192: 56112.466 | C192: 0.97073798
A193: C4DAAAAAAAAAAAAAAAAAAAAAAYGmZZmZmFmZGaGzAAAwAAAAzMzssMzELAAsNmZmZmtNbzMmlZmZMmZmhNmZmxAAYAAAgZmZWAAYGAA | B193: 56065.196 | C193: 0.96992022
A194: C4DAAAAAAAAAAAAAAAAAAAAAAYGmZZmZmFmZGaGzAAAwAAAAzMzssMzELAAsxMzMzstYbmxsMzMjxMzMsxMzMmBAYAAAgZmZWAAYGAA | B194: 56032.094 | C194: 0.96934756
...

Sheet Pivots
A1: Dimension: | B1: talent_str | D1: Metric: | E1: both
A2: Select a dimension and metric set to view the pivot table.
A5: Index | B5: =IF(LEN($B$1)=0,"(select dimension)",$B$1) -> 0 | C5: =IFERROR(INDEX(INDIRECT("pivot_" & SUBSTITUTE($B$1," ","_") & "_" & IF(LEN($E$1)=0,"both",$E$1) & "_headers"),1,COLUMN()-COLUMN($C$5)+2),"") -> 0 | D5: =IFERROR(INDEX(INDIRECT("pivot_" & SUBSTITUTE($B$1," ","_") & "_" & IF(LEN($E$1)=0,"both",$E$1) & "_headers"),1,COLUMN()-COLUMN($C$5)+2),"") -> 0 | E5: =IFERROR(INDEX(INDIRECT("pivot_" & SUBSTITUTE($B$1," ","_") & "_" & IF(LEN($E$1)=0,"both",$E$1) & "_headers"),1,COLUMN()-COLUMN($C$5)+2),"") -> 0
A6: 1 | B6: =IF($A6<=ROWS(INDIRECT("pivot_" & SUBSTITUTE($B$1," ","_") & "_" & IF(LEN($E$1)=0,"both",$E$1) & "_data")),INDEX(INDIRECT("pivot_" & SUBSTITUTE($B$1," ","_") & "_" & IF(LEN($E$1)=0,"both",$E$1) & "_data"),$A6,1),"") -> 0 | C6: =IF($A6<=ROWS(INDIRECT("pivot_" & SUBSTITUTE($B$1," ","_") & "_" & IF(LEN($E$1)=0,"both",$E$1) & "_data")),IF(COLUMN()-COLUMN($C$5)+2<=COLUMNS(INDIRECT("pivot_" & SUBSTITUTE($B$1," ","_") & "_" & IF(LEN($E$1)=0,"both",$E$1) & "_data")),INDEX(INDIRECT("pivot_" & SUBSTITUTE($B$1," ","_") & "_" & IF(LEN($E$1)=0,"both",$E$1) & "_data"),$A6,COLUMN()-COLUMN($C$5)+2),""),"") -> 0 | D6: =IF($A6<=ROWS(INDIRECT("pivot_" & SUBSTITUTE($B$1," ","_") & "_" & IF(LEN($E$1)=0,"both",$E$1) & "_data")),IF(COLUMN()-COLUMN($C$5)+2<=COLUMNS(INDIRECT("pivot_" & SUBSTITUTE($B$1," ","_") & "_" & IF(LEN($E$1)=0,"both",$E$1) & "_data")),INDEX(INDIRECT("pivot_" & SUBSTITUTE($B$1," ","_") & "_" & IF(LEN($E$1)=0,"both",$E$1) & "_data"),$A6,COLUMN()-COLUMN($C$5)+2),""),"") -> 0 | E6: =IF($A6<=ROWS(INDIRECT("pivot_" & SUBSTITUTE($B$1," ","_") & "_" & IF(LEN($E$1)=0,"both",$E$1) & "_data")),IF(COLUMN()-COLUMN($C$5)+2<=COLUMNS(INDIRECT("pivot_" & SUBSTITUTE($B$1," ","_") & "_" & IF(LEN($E$1)=0,"both",$E$1) & "_data")),INDEX(INDIRECT("pivot_" & SUBSTITUTE($B$1," ","_") & "_" & IF(LEN($E$1)=0,"both",$E$1) & "_data"),$A6,COLUMN()-COLUMN($C$5)+2),""),"") -> 0
A7: 2 | B7: =IF($A7<=ROWS(INDIRECT("pivot_" & SUBSTITUTE($B$1," ","_") & "_" & IF(LEN($E$1)=0,"both",$E$1) & "_data")),INDEX(INDIRECT("pivot_" & SUBSTITUTE($B$1," ","_") & "_" & IF(LEN($E$1)=0,"both",$E$1) & "_data"),$A7,1),"") -> 0 | C7: =IF($A7<=ROWS(INDIRECT("pivot_" & SUBSTITUTE($B$1," ","_") & "_" & IF(LEN($E$1)=0,"both",$E$1) & "_data")),IF(COLUMN()-COLUMN($C$5)+2<=COLUMNS(INDIRECT("pivot_" & SUBSTITUTE($B$1," ","_") & "_" & IF(LEN($E$1)=0,"both",$E$1) & "_data")),INDEX(INDIRECT("pivot_" & SUBSTITUTE($B$1," ","_") & "_" & IF(LEN($E$1)=0,"both",$E$1) & "_data"),$A7,COLUMN()-COLUMN($C$5)+2),""),"") -> 0 | D7: =IF($A7<=ROWS(INDIRECT("pivot_" & SUBSTITUTE($B$1," ","_") & "_" & IF(LEN($E$1)=0,"both",$E$1) & "_data")),IF(COLUMN()-COLUMN($C$5)+2<=COLUMNS(INDIRECT("pivot_" & SUBSTITUTE($B$1," ","_") & "_" & IF(LEN($E$1)=0,"both",$E$1) & "_data")),INDEX(INDIRECT("pivot_" & SUBSTITUTE($B$1," ","_") & "_" & IF(LEN($E$1)=0,"both",$E$1) & "_data"),$A7,COLUMN()-COLUMN($C$5)+2),""),"") -> 0 | E7: =IF($A7<=ROWS(INDIRECT("pivot_" & SUBSTITUTE($B$1," ","_") & "_" & IF(LEN($E$1)=0,"both",$E$1) & "_data")),IF(COLUMN()-COLUMN($C$5)+2<=COLUMNS(INDIRECT("pivot_" & SUBSTITUTE($B$1," ","_") & "_" & IF(LEN($E$1)=0,"both",$E$1) & "_data")),INDEX(INDIRECT("pivot_" & SUBSTITUTE($B$1," ","_") & "_" & IF(LEN($E$1)=0,"both",$E$1) & "_data"),$A7,COLUMN()-COLUMN($C$5)+2),""),"") -> 0
A8: 3 | B8: =IF($A8<=ROWS(INDIRECT("pivot_" & SUBSTITUTE($B$1," ","_") & "_" & IF(LEN($E$1)=0,"both",$E$1) & "_data")),INDEX(INDIRECT("pivot_" & SUBSTITUTE($B$1," ","_") & "_" & IF(LEN($E$1)=0,"both",$E$1) & "_data"),$A8,1),"") -> 0 | C8: =IF($A8<=ROWS(INDIRECT("pivot_" & SUBSTITUTE($B$1," ","_") & "_" & IF(LEN($E$1)=0,"both",$E$1) & "_data")),IF(COLUMN()-COLUMN($C$5)+2<=COLUMNS(INDIRECT("pivot_" & SUBSTITUTE($B$1," ","_") & "_" & IF(LEN($E$1)=0,"both",$E$1) & "_data")),INDEX(INDIRECT("pivot_" & SUBSTITUTE($B$1," ","_") & "_" & IF(LEN($E$1)=0,"both",$E$1) & "_data"),$A8,COLUMN()-COLUMN($C$5)+2),""),"") -> 0 | D8: =IF($A8<=ROWS(INDIRECT("pivot_" & SUBSTITUTE($B$1," ","_") & "_" & IF(LEN($E$1)=0,"both",$E$1) & "_data")),IF(COLUMN()-COLUMN($C$5)+2<=COLUMNS(INDIRECT("pivot_" & SUBSTITUTE($B$1," ","_") & "_" & IF(LEN($E$1)=0,"both",$E$1) & "_data")),INDEX(INDIRECT("pivot_" & SUBSTITUTE($B$1," ","_") & "_" & IF(LEN($E$1)=0,"both",$E$1) & "_data"),$A8,COLUMN()-COLUMN($C$5)+2),""),"") -> 0 | E8: =IF($A8<=ROWS(INDIRECT("pivot_" & SUBSTITUTE($B$1," ","_") & "_" & IF(LEN($E$1)=0,"both",$E$1) & "_data")),IF(COLUMN()-COLUMN($C$5)+2<=COLUMNS(INDIRECT("pivot_" & SUBSTITUTE($B$1," ","_") & "_" & IF(LEN($E$1)=0,"both",$E$1) & "_data")),INDEX(INDIRECT("pivot_" & SUBSTITUTE($B$1," ","_") & "_" & IF(LEN($E$1)=0,"both",$E$1) & "_data"),$A8,COLUMN()-COLUMN($C$5)+2),""),"") -> 0
A9: 4 | B9: =IF($A9<=ROWS(INDIRECT("pivot_" & SUBSTITUTE($B$1," ","_") & "_" & IF(LEN($E$1)=0,"both",$E$1) & "_data")),INDEX(INDIRECT("pivot_" & SUBSTITUTE($B$1," ","_") & "_" & IF(LEN($E$1)=0,"both",$E$1) & "_data"),$A9,1),"") -> 0 | C9: =IF($A9<=ROWS(INDIRECT("pivot_" & SUBSTITUTE($B$1," ","_") & "_" & IF(LEN($E$1)=0,"both",$E$1) & "_data")),IF(COLUMN()-COLUMN($C$5)+2<=COLUMNS(INDIRECT("pivot_" & SUBSTITUTE($B$1," ","_") & "_" & IF(LEN($E$1)=0,"both",$E$1) & "_data")),INDEX(INDIRECT("pivot_" & SUBSTITUTE($B$1," ","_") & "_" & IF(LEN($E$1)=0,"both",$E$1) & "_data"),$A9,COLUMN()-COLUMN($C$5)+2),""),"") -> 0 | D9: =IF($A9<=ROWS(INDIRECT("pivot_" & SUBSTITUTE($B$1," ","_") & "_" & IF(LEN($E$1)=0,"both",$E$1) & "_data")),IF(COLUMN()-COLUMN($C$5)+2<=COLUMNS(INDIRECT("pivot_" & SUBSTITUTE($B$1," ","_") & "_" & IF(LEN($E$1)=0,"both",$E$1) & "_data")),INDEX(INDIRECT("pivot_" & SUBSTITUTE($B$1," ","_") & "_" & IF(LEN($E$1)=0,"both",$E$1) & "_data"),$A9,COLUMN()-COLUMN($C$5)+2),""),"") -> 0 | E9: =IF($A9<=ROWS(INDIRECT("pivot_" & SUBSTITUTE($B$1," ","_") & "_" & IF(LEN($E$1)=0,"both",$E$1) & "_data")),IF(COLUMN()-COLUMN($C$5)+2<=COLUMNS(INDIRECT("pivot_" & SUBSTITUTE($B$1," ","_") & "_" & IF(LEN($E$1)=0,"both",$E$1) & "_data")),INDEX(INDIRECT("pivot_" & SUBSTITUTE($B$1," ","_") & "_" & IF(LEN($E$1)=0,"both",$E$1) & "_data"),$A9,COLUMN()-COLUMN($C$5)+2),""),"") -> 0
A10: 5 | B10: =IF($A10<=ROWS(INDIRECT("pivot_" & SUBSTITUTE($B$1," ","_") & "_" & IF(LEN($E$1)=0,"both",$E$1) & "_data")),INDEX(INDIRECT("pivot_" & SUBSTITUTE($B$1," ","_") & "_" & IF(LEN($E$1)=0,"both",$E$1) & "_data"),$A10,1),"") -> 0 | C10: =IF($A10<=ROWS(INDIRECT("pivot_" & SUBSTITUTE($B$1," ","_") & "_" & IF(LEN($E$1)=0,"both",$E$1) & "_data")),IF(COLUMN()-COLUMN($C$5)+2<=COLUMNS(INDIRECT("pivot_" & SUBSTITUTE($B$1," ","_") & "_" & IF(LEN($E$1)=0,"both",$E$1) & "_data")),INDEX(INDIRECT("pivot_" & SUBSTITUTE($B$1," ","_") & "_" & IF(LEN($E$1)=0,"both",$E$1) & "_data"),$A10,COLUMN()-COLUMN($C$5)+2),""),"") -> 0 | D10: =IF($A10<=ROWS(INDIRECT("pivot_" & SUBSTITUTE($B$1," ","_") & "_" & IF(LEN($E$1)=0,"both",$E$1) & "_data")),IF(COLUMN()-COLUMN($C$5)+2<=COLUMNS(INDIRECT("pivot_" & SUBSTITUTE($B$1," ","_") & "_" & IF(LEN($E$1)=0,"both",$E$1) & "_data")),INDEX(INDIRECT("pivot_" & SUBSTITUTE($B$1," ","_") & "_" & IF(LEN($E$1)=0,"both",$E$1) & "_data"),$A10,COLUMN()-COLUMN($C$5)+2),""),"") -> 0 | E10: =IF($A10<=ROWS(INDIRECT("pivot_" & SUBSTITUTE($B$1," ","_") & "_" & IF(LEN($E$1)=0,"both",$E$1) & "_data")),IF(COLUMN()-COLUMN($C$5)+2<=COLUMNS(INDIRECT("pivot_" & SUBSTITUTE($B$1," ","_") & "_" & IF(LEN($E$1)=0,"both",$E$1) & "_data")),INDEX(INDIRECT("pivot_" & SUBSTITUTE($B$1," ","_") & "_" & IF(LEN($E$1)=0,"both",$E$1) & "_data"),$A10,COLUMN()-COLUMN($C$5)+2),""),"") -> 0
A11: 6 | B11: =IF($A11<=ROWS(INDIRECT("pivot_" & SUBSTITUTE($B$1," ","_") & "_" & IF(LEN($E$1)=0,"both",$E$1) & "_data")),INDEX(INDIRECT("pivot_" & SUBSTITUTE($B$1," ","_") & "_" & IF(LEN($E$1)=0,"both",$E$1) & "_data"),$A11,1),"") -> 0 | C11: =IF($A11<=ROWS(INDIRECT("pivot_" & SUBSTITUTE($B$1," ","_") & "_" & IF(LEN($E$1)=0,"both",$E$1) & "_data")),IF(COLUMN()-COLUMN($C$5)+2<=COLUMNS(INDIRECT("pivot_" & SUBSTITUTE($B$1," ","_") & "_" & IF(LEN($E$1)=0,"both",$E$1) & "_data")),INDEX(INDIRECT("pivot_" & SUBSTITUTE($B$1," ","_") & "_" & IF(LEN($E$1)=0,"both",$E$1) & "_data"),$A11,COLUMN()-COLUMN($C$5)+2),""),"") -> 0 | D11: =IF($A11<=ROWS(INDIRECT("pivot_" & SUBSTITUTE($B$1," ","_") & "_" & IF(LEN($E$1)=0,"both",$E$1) & "_data")),IF(COLUMN()-COLUMN($C$5)+2<=COLUMNS(INDIRECT("pivot_" & SUBSTITUTE($B$1," ","_") & "_" & IF(LEN($E$1)=0,"both",$E$1) & "_data")),INDEX(INDIRECT("pivot_" & SUBSTITUTE($B$1," ","_") & "_" & IF(LEN($E$1)=0,"both",$E$1) & "_data"),$A11,COLUMN()-COLUMN($C$5)+2),""),"") -> 0 | E11: =IF($A11<=ROWS(INDIRECT("pivot_" & SUBSTITUTE($B$1," ","_") & "_" & IF(LEN($E$1)=0,"both",$E$1) & "_data")),IF(COLUMN()-COLUMN($C$5)+2<=COLUMNS(INDIRECT("pivot_" & SUBSTITUTE($B$1," ","_") & "_" & IF(LEN($E$1)=0,"both",$E$1) & "_data")),INDEX(INDIRECT("pivot_" & SUBSTITUTE($B$1," ","_") & "_" & IF(LEN($E$1)=0,"both",$E$1) & "_data"),$A11,COLUMN()-COLUMN($C$5)+2),""),"") -> 0
A12: 7 | B12: =IF($A12<=ROWS(INDIRECT("pivot_" & SUBSTITUTE($B$1," ","_") & "_" & IF(LEN($E$1)=0,"both",$E$1) & "_data")),INDEX(INDIRECT("pivot_" & SUBSTITUTE($B$1," ","_") & "_" & IF(LEN($E$1)=0,"both",$E$1) & "_data"),$A12,1),"") -> 0 | C12: =IF($A12<=ROWS(INDIRECT("pivot_" & SUBSTITUTE($B$1," ","_") & "_" & IF(LEN($E$1)=0,"both",$E$1) & "_data")),IF(COLUMN()-COLUMN($C$5)+2<=COLUMNS(INDIRECT("pivot_" & SUBSTITUTE($B$1," ","_") & "_" & IF(LEN($E$1)=0,"both",$E$1) & "_data")),INDEX(INDIRECT("pivot_" & SUBSTITUTE($B$1," ","_") & "_" & IF(LEN($E$1)=0,"both",$E$1) & "_data"),$A12,COLUMN()-COLUMN($C$5)+2),""),"") -> 0 | D12: =IF($A12<=ROWS(INDIRECT("pivot_" & SUBSTITUTE($B$1," ","_") & "_" & IF(LEN($E$1)=0,"both",$E$1) & "_data")),IF(COLUMN()-COLUMN($C$5)+2<=COLUMNS(INDIRECT("pivot_" & SUBSTITUTE($B$1," ","_") & "_" & IF(LEN($E$1)=0,"both",$E$1) & "_data")),INDEX(INDIRECT("pivot_" & SUBSTITUTE($B$1," ","_") & "_" & IF(LEN($E$1)=0,"both",$E$1) & "_data"),$A12,COLUMN()-COLUMN($C$5)+2),""),"") -> 0 | E12: =IF($A12<=ROWS(INDIRECT("pivot_" & SUBSTITUTE($B$1," ","_") & "_" & IF(LEN($E$1)=0,"both",$E$1) & "_data")),IF(COLUMN()-COLUMN($C$5)+2<=COLUMNS(INDIRECT("pivot_" & SUBSTITUTE($B$1," ","_") & "_" & IF(LEN($E$1)=0,"both",$E$1) & "_data")),INDEX(INDIRECT("pivot_" & SUBSTITUTE($B$1," ","_") & "_" & IF(LEN($E$1)=0,"both",$E$1) & "_data"),$A12,COLUMN()-COLUMN($C$5)+2),""),"") -> 0
A13: 8 | B13: =IF($A13<=ROWS(INDIRECT("pivot_" & SUBSTITUTE($B$1," ","_") & "_" & IF(LEN($E$1)=0,"both",$E$1) & "_data")),INDEX(INDIRECT("pivot_" & SUBSTITUTE($B$1," ","_") & "_" & IF(LEN($E$1)=0,"both",$E$1) & "_data"),$A13,1),"") -> 0 | C13: =IF($A13<=ROWS(INDIRECT("pivot_" & SUBSTITUTE($B$1," ","_") & "_" & IF(LEN($E$1)=0,"both",$E$1) & "_data")),IF(COLUMN()-COLUMN($C$5)+2<=COLUMNS(INDIRECT("pivot_" & SUBSTITUTE($B$1," ","_") & "_" & IF(LEN($E$1)=0,"both",$E$1) & "_data")),INDEX(INDIRECT("pivot_" & SUBSTITUTE($B$1," ","_") & "_" & IF(LEN($E$1)=0,"both",$E$1) & "_data"),$A13,COLUMN()-COLUMN($C$5)+2),""),"") -> 0 | D13: =IF($A13<=ROWS(INDIRECT("pivot_" & SUBSTITUTE($B$1," ","_") & "_" & IF(LEN($E$1)=0,"both",$E$1) & "_data")),IF(COLUMN()-COLUMN($C$5)+2<=COLUMNS(INDIRECT("pivot_" & SUBSTITUTE($B$1," ","_") & "_" & IF(LEN($E$1)=0,"both",$E$1) & "_data")),INDEX(INDIRECT("pivot_" & SUBSTITUTE($B$1," ","_") & "_" & IF(LEN($E$1)=0,"both",$E$1) & "_data"),$A13,COLUMN()-COLUMN($C$5)+2),""),"") -> 0 | E13: =IF($A13<=ROWS(INDIRECT("pivot_" & SUBSTITUTE($B$1," ","_") & "_" & IF(LEN($E$1)=0,"both",$E$1) & "_data")),IF(COLUMN()-COLUMN($C$5)+2<=COLUMNS(INDIRECT("pivot_" & SUBSTITUTE($B$1," ","_") & "_" & IF(LEN($E$1)=0,"both",$E$1) & "_data")),INDEX(INDIRECT("pivot_" & SUBSTITUTE($B$1," ","_") & "_" & IF(LEN($E$1)=0,"both",$E$1) & "_data"),$A13,COLUMN()-COLUMN($C$5)+2),""),"") -> 0
A14: 9 | B14: =IF($A14<=ROWS(INDIRECT("pivot_" & SUBSTITUTE($B$1," ","_") & "_" & IF(LEN($E$1)=0,"both",$E$1) & "_data")),INDEX(INDIRECT("pivot_" & SUBSTITUTE($B$1," ","_") & "_" & IF(LEN($E$1)=0,"both",$E$1) & "_data"),$A14,1),"") -> 0 | C14: =IF($A14<=ROWS(INDIRECT("pivot_" & SUBSTITUTE($B$1," ","_") & "_" & IF(LEN($E$1)=0,"both",$E$1) & "_data")),IF(COLUMN()-COLUMN($C$5)+2<=COLUMNS(INDIRECT("pivot_" & SUBSTITUTE($B$1," ","_") & "_" & IF(LEN($E$1)=0,"both",$E$1) & "_data")),INDEX(INDIRECT("pivot_" & SUBSTITUTE($B$1," ","_") & "_" & IF(LEN($E$1)=0,"both",$E$1) & "_data"),$A14,COLUMN()-COLUMN($C$5)+2),""),"") -> 0 | D14: =IF($A14<=ROWS(INDIRECT("pivot_" & SUBSTITUTE($B$1," ","_") & "_" & IF(LEN($E$1)=0,"both",$E$1) & "_data")),IF(COLUMN()-COLUMN($C$5)+2<=COLUMNS(INDIRECT("pivot_" & SUBSTITUTE($B$1," ","_") & "_" & IF(LEN($E$1)=0,"both",$E$1) & "_data")),INDEX(INDIRECT("pivot_" & SUBSTITUTE($B$1," ","_") & "_" & IF(LEN($E$1)=0,"both",$E$1) & "_data"),$A14,COLUMN()-COLUMN($C$5)+2),""),"") -> 0 | E14: =IF($A14<=ROWS(INDIRECT("pivot_" & SUBSTITUTE($B$1," ","_") & "_" & IF(LEN($E$1)=0,"both",$E$1) & "_data")),IF(COLUMN()-COLUMN($C$5)+2<=COLUMNS(INDIRECT("pivot_" & SUBSTITUTE($B$1," ","_") & "_" & IF(LEN($E$1)=0,"both",$E$1) & "_data")),INDEX(INDIRECT("pivot_" & SUBSTITUTE($B$1," ","_") & "_" & IF(LEN($E$1)=0,"both",$E$1) & "_data"),$A14,COLUMN()-COLUMN($C$5)+2),""),"") -> 0
A15: 10 | B15: =IF($A15<=ROWS(INDIRECT("pivot_" & SUBSTITUTE($B$1," ","_") & "_" & IF(LEN($E$1)=0,"both",$E$1) & "_data")),INDEX(INDIRECT("pivot_" & SUBSTITUTE($B$1," ","_") & "_" & IF(LEN($E$1)=0,"both",$E$1) & "_data"),$A15,1),"") -> 0 | C15: =IF($A15<=ROWS(INDIRECT("pivot_" & SUBSTITUTE($B$1," ","_") & "_" & IF(LEN($E$1)=0,"both",$E$1) & "_data")),IF(COLUMN()-COLUMN($C$5)+2<=COLUMNS(INDIRECT("pivot_" & SUBSTITUTE($B$1," ","_") & "_" & IF(LEN($E$1)=0,"both",$E$1) & "_data")),INDEX(INDIRECT("pivot_" & SUBSTITUTE($B$1," ","_") & "_" & IF(LEN($E$1)=0,"both",$E$1) & "_data"),$A15,COLUMN()-COLUMN($C$5)+2),""),"") -> 0 | D15: =IF($A15<=ROWS(INDIRECT("pivot_" & SUBSTITUTE($B$1," ","_") & "_" & IF(LEN($E$1)=0,"both",$E$1) & "_data")),IF(COLUMN()-COLUMN($C$5)+2<=COLUMNS(INDIRECT("pivot_" & SUBSTITUTE($B$1," ","_") & "_" & IF(LEN($E$1)=0,"both",$E$1) & "_data")),INDEX(INDIRECT("pivot_" & SUBSTITUTE($B$1," ","_") & "_" & IF(LEN($E$1)=0,"both",$E$1) & "_data"),$A15,COLUMN()-COLUMN($C$5)+2),""),"") -> 0 | E15: =IF($A15<=ROWS(INDIRECT("pivot_" & SUBSTITUTE($B$1," ","_") & "_" & IF(LEN($E$1)=0,"both",$E$1) & "_data")),IF(COLUMN()-COLUMN($C$5)+2<=COLUMNS(INDIRECT("pivot_" & SUBSTITUTE($B$1," ","_") & "_" & IF(LEN($E$1)=0,"both",$E$1) & "_data")),INDEX(INDIRECT("pivot_" & SUBSTITUTE($B$1," ","_") & "_" & IF(LEN($E$1)=0,"both",$E$1) & "_data"),$A15,COLUMN()-COLUMN($C$5)+2),""),"") -> 0
A16: 11 | B16: =IF($A16<=ROWS(INDIRECT("pivot_" & SUBSTITUTE($B$1," ","_") & "_" & IF(LEN($E$1)=0,"both",$E$1) & "_data")),INDEX(INDIRECT("pivot_" & SUBSTITUTE($B$1," ","_") & "_" & IF(LEN($E$1)=0,"both",$E$1) & "_data"),$A16,1),"") -> 0 | C16: =IF($A16<=ROWS(INDIRECT("pivot_" & SUBSTITUTE($B$1," ","_") & "_" & IF(LEN($E$1)=0,"both",$E$1) & "_data")),IF(COLUMN()-COLUMN($C$5)+2<=COLUMNS(INDIRECT("pivot_" & SUBSTITUTE($B$1," ","_") & "_" & IF(LEN($E$1)=0,"both",$E$1) & "_data")),INDEX(INDIRECT("pivot_" & SUBSTITUTE($B$1," ","_") & "_" & IF(LEN($E$1)=0,"both",$E$1) & "_data"),$A16,COLUMN()-COLUMN($C$5)+2),""),"") -> 0 | D16: =IF($A16<=ROWS(INDIRECT("pivot_" & SUBSTITUTE($B$1," ","_") & "_" & IF(LEN($E$1)=0,"both",$E$1) & "_data")),IF(COLUMN()-COLUMN($C$5)+2<=COLUMNS(INDIRECT("pivot_" & SUBSTITUTE($B$1," ","_") & "_" & IF(LEN($E$1)=0,"both",$E$1) & "_data")),INDEX(INDIRECT("pivot_" & SUBSTITUTE($B$1," ","_") & "_" & IF(LEN($E$1)=0,"both",$E$1) & "_data"),$A16,COLUMN()-COLUMN($C$5)+2),""),"") -> 0 | E16: =IF($A16<=ROWS(INDIRECT("pivot_" & SUBSTITUTE($B$1," ","_") & "_" & IF(LEN($E$1)=0,"both",$E$1) & "_data")),IF(COLUMN()-COLUMN($C$5)+2<=COLUMNS(INDIRECT("pivot_" & SUBSTITUTE($B$1," ","_") & "_" & IF(LEN($E$1)=0,"both",$E$1) & "_data")),INDEX(INDIRECT("pivot_" & SUBSTITUTE($B$1," ","_") & "_" & IF(LEN($E$1)=0,"both",$E$1) & "_data"),$A16,COLUMN()-COLUMN($C$5)+2),""),"") -> 0
A17: 12 | B17: =IF($A17<=ROWS(INDIRECT("pivot_" & SUBSTITUTE($B$1," ","_") & "_" & IF(LEN($E$1)=0,"both",$E$1) & "_data")),INDEX(INDIRECT("pivot_" & SUBSTITUTE($B$1," ","_") & "_" & IF(LEN($E$1)=0,"both",$E$1) & "_data"),$A17,1),"") -> 0 | C17: =IF($A17<=ROWS(INDIRECT("pivot_" & SUBSTITUTE($B$1," ","_") & "_" & IF(LEN($E$1)=0,"both",$E$1) & "_data")),IF(COLUMN()-COLUMN($C$5)+2<=COLUMNS(INDIRECT("pivot_" & SUBSTITUTE($B$1," ","_") & "_" & IF(LEN($E$1)=0,"both",$E$1) & "_data")),INDEX(INDIRECT("pivot_" & SUBSTITUTE($B$1," ","_") & "_" & IF(LEN($E$1)=0,"both",$E$1) & "_data"),$A17,COLUMN()-COLUMN($C$5)+2),""),"") -> 0 | D17: =IF($A17<=ROWS(INDIRECT("pivot_" & SUBSTITUTE($B$1," ","_") & "_" & IF(LEN($E$1)=0,"both",$E$1) & "_data")),IF(COLUMN()-COLUMN($C$5)+2<=COLUMNS(INDIRECT("pivot_" & SUBSTITUTE($B$1," ","_") & "_" & IF(LEN($E$1)=0,"both",$E$1) & "_data")),INDEX(INDIRECT("pivot_" & SUBSTITUTE($B$1," ","_") & "_" & IF(LEN($E$1)=0,"both",$E$1) & "_data"),$A17,COLUMN()-COLUMN($C$5)+2),""),"") -> 0 | E17: =IF($A17<=ROWS(INDIRECT("pivot_" & SUBSTITUTE($B$1," ","_") & "_" & IF(LEN($E$1)=0,"both",$E$1) & "_data")),IF(COLUMN()-COLUMN($C$5)+2<=COLUMNS(INDIRECT("pivot_" & SUBSTITUTE($B$1," ","_") & "_" & IF(LEN($E$1)=0,"both",$E$1) & "_data")),INDEX(INDIRECT("pivot_" & SUBSTITUTE($B$1," ","_") & "_" & IF(LEN($E$1)=0,"both",$E$1) & "_data"),$A17,COLUMN()-COLUMN($C$5)+2),""),"") -> 0
... A94: 89 | B94: =IF($A94<=ROWS(INDIRECT("pivot_" & SUBSTITUTE($B$1," ","_") & "_" & IF(LEN($E$1)=0,"both",$E$1) & "_data")),INDEX(INDIRECT("pivot_" & SUBSTITUTE($B$1," ","_") & "_" & IF(LEN($E$1)=0,"both",$E$1) & "_data"),$A94,1),"") -> 0 | C94: =IF($A94<=ROWS(INDIRECT("pivot_" & SUBSTITUTE($B$1," ","_") & "_" & IF(LEN($E$1)=0,"both",$E$1) & "_data")),IF(COLUMN()-COLUMN($C$5)+2<=COLUMNS(INDIRECT("pivot_" & SUBSTITUTE($B$1," ","_") & "_" & IF(LEN($E$1)=0,"both",$E$1) & "_data")),INDEX(INDIRECT("pivot_" & SUBSTITUTE($B$1," ","_") & "_" & IF(LEN($E$1)=0,"both",$E$1) & "_data"),$A94,COLUMN()-COLUMN($C$5)+2),""),"") -> 0 | D94: =IF($A94<=ROWS(INDIRECT("pivot_" & SUBSTITUTE($B$1," ","_") & "_" & IF(LEN($E$1)=0,"both",$E$1) & "_data")),IF(COLUMN()-COLUMN($C$5)+2<=COLUMNS(INDIRECT("pivot_" & SUBSTITUTE($B$1," ","_") & "_" & IF(LEN($E$1)=0,"both",$E$1) & "_data")),INDEX(INDIRECT("pivot_" & SUBSTITUTE($B$1," ","_") & "_" & IF(LEN($E$1)=0,"both",$E$1) & "_data"),$A94,COLUMN()-COLUMN($C$5)+2),""),"") -> 0 | E94: =IF($A94<=ROWS(INDIRECT("pivot_" & SUBSTITUTE($B$1," ","_") & "_" & IF(LEN($E$1)=0,"both",$E$1) & "_data")),IF(COLUMN()-COLUMN($C$5)+2<=COLUMNS(INDIRECT("pivot_" & SUBSTITUTE($B$1," ","_") & "_" & IF(LEN($E$1)=0,"both",$E$1) & "_data")),INDEX(INDIRECT("pivot_" & SUBSTITUTE($B$1," ","_") & "_" & IF(LEN($E$1)=0,"both",$E$1) & "_data"),$A94,COLUMN()-COLUMN($C$5)+2),""),"") -> 0

Sheet Talents
A1: No talent columns detected.

Sheet Ranked Chart
A1: Source: | B1: Summary | C1: Max | D1: =MAX($C$6:$C$25) -> 0
C2: Min | D2: =MIN($C$6:$C$25) -> 0
A3: ="Scale: "&TEXT($D$3,"0%")&" – "&TEXT($D$4,"0%") -> 0 | C3: Lower | D3: =IF($D$2>0.95,0.95,IF($D$2>0.9,0.9,IF($D$2>0.8,0.8,IF($D$2>0.6,0.6,IF($D$2>0.4,0.4,0.2))))) -> 0
C4: Upper | D4: =IF($D$1<=0.4,0.4,IF($D$1<=0.6,0.6,IF($D$1<=0.8,0.8,IF($D$1<=0.9,0.9,IF($D$1<=0.95,0.95,1))))) -> 0
A5: Label | B5: Weighted Avg | C5: Num | E5: Relative | G5: Summary Labels | H5: Summary Values | I5: talent_str Labels | J5: talent_str Values | K5: race Labels | L5: race Values | M5: trinket Labels | N5: trinket Values | O5: stat_profile Labels | P5: stat_profile Values | Q5: trinket_pair Labels | R5: trinket_pair Values | S5: individual talents Labels | T5: individual talents Values
A6: =IFERROR(IF($B6="","",INDEX(('Ranked Chart'!$G$6:$G$25,'Ranked Chart'!$I$6:$I$25,'Ranked Chart'!$K$6:$K$25,'Ranked Chart'!$M$6:$M$25,'Ranked Chart'!$O$6:$O$25,'Ranked Chart'!$Q$6:$Q$25,'Ranked Chart'!$S$6:$S$25),ROWS($A$6:A6),1,MATCH($B$1,{"Summary","talent_str","race","trinket","stat_profile","trinket_pair","individual talents"},0))),"") -> 0 | B6: =IFERROR(IF(INDEX(('Ranked Chart'!$H$6:$H$25,'Ranked Chart'!$J$6:$J$25,'Ranked Chart'!$L$6:$L$25,'Ranked Chart'!$N$6:$N$25,'Ranked Chart'!$P$6:$P$25,'Ranked Chart'!$R$6:$R$25,'Ranked Chart'!$T$6:$T$25),ROWS($A$6:A6),1,MATCH($B$1,{"Summary","talent_str","race","trinket","stat_profile","trinket_pair","individual talents"},0))>0,INDEX(('Ranked Chart'!$H$6:$H$25,'Ranked Chart'!$J$6:$J$25,'Ranked Chart'!$L$6:$L$25,'Ranked Chart'!$N$6:$N$25,'Ranked Chart'!$P$6:$P$25,'Ranked Chart'!$R$6:$R$25,'Ranked Chart'!$T$6:$T$25),ROWS($A$6:A6),1,MATCH($B$1,{"Summary","talent_str","race","trinket","stat_profile","trinket_pair","individual talents"},0)),""),"") -> 0 | C6: =IF($B6="","",$B6) -> 0 | E6: =IF($A6="","",IF($D$4>$D$3,MAX(0,MIN($C6,$D$4)-$D$3)/($D$4-$D$3),"")) -> 0 | G6: Void Elf | galactic_gladiators_badge_of_ferocity + galactic_gladiators_insignia_of_alacrity | C4DAAAAAAAAAAAAAAAAAAAAAAYGmZZmZmFmZGaGzAAAwAAgAmZmZZZmJW… | H6: 1 | I6: C4DAAAAAAAAAAAAAAAAAAAAAAYGmZZmZmFmZGaGzAAAwAAgAmZmZZZmJWAAYbmZmZmZbx2MzMLjxYMzMGbMzMjBAwAAAAzMzsAAwMAA | J6: 1 | K6: Void Elf | L6: 1 | M6: galactic_gladiators_badge_of_ferocity | N6: 1 | O6: 602/1237/107/519 | P6: 1 | Q6: galactic_gladiators_badge_of_ferocity + galactic_gladiators_insignia_of_alacrity | R6: 1
A7: =IFERROR(IF($B7="","",INDEX(('Ranked Chart'!$G$6:$G$25,'Ranked Chart'!$I$6:$I$25,'Ranked Chart'!$K$6:$K$25,'Ranked Chart'!$M$6:$M$25,'Ranked Chart'!$O$6:$O$25,'Ranked Chart'!$Q$6:$Q$25,'Ranked Chart'!$S$6:$S$25),ROWS($A$6:A7),1,MATCH($B$1,{"Summary","talent_str","race","trinket","stat_profile","trinket_pair","individual talents"},0))),"") -> 0 | B7: =IFERROR(IF(INDEX(('Ranked Chart'!$H$6:$H$25,'Ranked Chart'!$J$6:$J$25,'Ranked Chart'!$L$6:$L$25,'Ranked Chart'!$N$6:$N$25,'Ranked Chart'!$P$6:$P$25,'Ranked Chart'!$R$6:$R$25,'Ranked Chart'!$T$6:$T$25),ROWS($A$6:A7),1,MATCH($B$1,{"Summary","talent_str","race","trinket","stat_profile","trinket_pair","individual talents"},0))>0,INDEX(('Ranked Chart'!$H$6:$H$25,'Ranked Chart'!$J$6:$J$25,'Ranked Chart'!$L$6:$L$25,'Ranked Chart'!$N$6:$N$25,'Ranked Chart'!$P$6:$P$25,'Ranked Chart'!$R$6:$R$25,'Ranked Chart'!$T$6:$T$25),ROWS($A$6:A7),1,MATCH($B$1,{"Summary","talent_str","race","trinket","stat_profile","trinket_pair","individual talents"},0)),""),"") -> 0 | C7: =IF($B7="","",$B7) -> 0 | E7: =IF($A7="","",IF($D$4>$D$3,MAX(0,MIN($C7,$D$4)-$D$3)/($D$4-$D$3),"")) -> 0 | G7: Void Elf | galactic_gladiators_badge_of_ferocity + galactic_gladiators_insignia_of_alacrity | C4DAAAAAAAAAAAAAAAAAAAAAAYGmZZmZmFmZGaGzAAAwAAAAzMzssMzEL… | H7: 0.98033602 | I7: C4DAAAAAAAAAAAAAAAAAAAAAAYGmZZmZmFmZGaGzAAAwAAAAzMzssMzELAAsNmZmZmtNLzMmlZmZMmZmhNmZmxAAYAAAgZmZWAAYGAA | J7: 0.98033602 | M7: galactic_gladiators_insignia_of_alacrity | N7: 1
A8: =IFERROR(IF($B8="","",INDEX(('Ranked Chart'!$G$6:$G$25,'Ranked Chart'!$I$6:$I$25,'Ranked Chart'!$K$6:$K$25,'Ranked Chart'!$M$6:$M$25,'Ranked Chart'!$O$6:$O$25,'Ranked Chart'!$Q$6:$Q$25,'Ranked Chart'!$S$6:$S$25),ROWS($A$6:A8),1,MATCH($B$1,{"Summary","talent_str","race","trinket","stat_profile","trinket_pair","individual talents"},0))),"") -> 0 | B8: =IFERROR(IF(INDEX(('Ranked Chart'!$H$6:$H$25,'Ranked Chart'!$J$6:$J$25,'Ranked Chart'!$L$6:$L$25,'Ranked Chart'!$N$6:$N$25,'Ranked Chart'!$P$6:$P$25,'Ranked Chart'!$R$6:$R$25,'Ranked Chart'!$T$6:$T$25),ROWS($A$6:A8),1,MATCH($B$1,{"Summary","talent_str","race","trinket","stat_profile","trinket_pair","individual talents"},0))>0,INDEX(('Ranked Chart'!$H$6:$H$25,'Ranked Chart'!$J$6:$J$25,'Ranked Chart'!$L$6:$L$25,'Ranked Chart'!$N$6:$N$25,'Ranked Chart'!$P$6:$P$25,'Ranked Chart'!$R$6:$R$25,'Ranked Chart'!$T$6:$T$25),ROWS($A$6:A8),1,MATCH($B$1,{"Summary","talent_str","race","trinket","stat_profile","trinket_pair","individual talents"},0)),""),"") -> 0 | C8: =IF($B8="","",$B8) -> 0 | E8: =IF($A8="","",IF($D$4>$D$3,MAX(0,MIN($C8,$D$4)-$D$3)/($D$4-$D$3),"")) -> 0 | G8: Void Elf | galactic_gladiators_badge_of_ferocity + galactic_gladiators_insignia_of_alacrity | C4DAAAAAAAAAAAAAAAAAAAAAAYGmZZmZmFmZGaGzAAAwAAAAzMzssMzEL… | H8: 0.97931104 | I8: C4DAAAAAAAAAAAAAAAAAAAAAAYGmZZmZmFmZGaGzAAAwAAAAzMzssMzELAAsNmZmZmtNLzMmlxMjxMzMsxMzMmBAYAAAgZmZWAAYGAA | J8: 0.97931104
A9: =IFERROR(IF($B9="","",INDEX(('Ranked Chart'!$G$6:$G$25,'Ranked Chart'!$I$6:$I$25,'Ranked Chart'!$K$6:$K$25,'Ranked Chart'!$M$6:$M$25,'Ranked Chart'!$O$6:$O$25,'Ranked Chart'!$Q$6:$Q$25,'Ranked Chart'!$S$6:$S$25),ROWS($A$6:A9),1,MATCH($B$1,{"Summary","talent_str","race","trinket","stat_profile","trinket_pair","individual talents"},0))),"") -> 0 | B9: =IFERROR(IF(INDEX(('Ranked Chart'!$H$6:$H$25,'Ranked Chart'!$J$6:$J$25,'Ranked Chart'!$L$6:$L$25,'Ranked Chart'!$N$6:$N$25,'Ranked Chart'!$P$6:$P$25,'Ranked Chart'!$R$6:$R$25,'Ranked Chart'!$T$6:$T$25),ROWS($A$6:A9),1,MATCH($B$1,{"Summary","talent_str","race","trinket","stat_profile","trinket_pair","individual talents"},0))>0,INDEX(('Ranked Chart'!$H$6:$H$25,'Ranked Chart'!$J$6:$J$25,'Ranked Chart'!$L$6:$L$25,'Ranked Chart'!$N$6:$N$25,'Ranked Chart'!$P$6:$P$25,'Ranked Chart'!$R$6:$R$25,'Ranked Chart'!$T$6:$T$25),ROWS($A$6:A9),1,MATCH($B$1,{"Summary","talent_str","race","trinket","stat_profile","trinket_pair","individual talents"},0)),""),"") -> 0 | C9: =IF($B9="","",$B9) -> 0 | E9: =IF($A9="","",IF($D$4>$D$3,MAX(0,MIN($C9,$D$4)-$D$3)/($D$4-$D$3),"")) -> 0 | G9: Void Elf | galactic_gladiators_badge_of_ferocity + galactic_gladiators_insignia_of_alacrity | C4DAAAAAAAAAAAAAAAAAAAAAAYGmZZmZmFmZGaGzAAAwAAAAzMzssMzEL… | H9: 0.97881554 | I9: C4DAAAAAAAAAAAAAAAAAAAAAAYGmZZmZmFmZGaGzAAAwAAAAzMzssMzELAAsNmZmZmtFLzMmlZmZMmZmhNmZmxAAYAAAgZmZWAAYGAA | J9: 0.97881554
A10: =IFERROR(IF($B10="","",INDEX(('Ranked Chart'!$G$6:$G$25,'Ranked Chart'!$I$6:$I$25,'Ranked Chart'!$K$6:$K$25,'Ranked Chart'!$M$6:$M$25,'Ranked Chart'!$O$6:$O$25,'Ranked Chart'!$Q$6:$Q$25,'Ranked Chart'!$S$6:$S$25),ROWS($A$6:A10),1,MATCH($B$1,{"Summary","talent_str","race","trinket","stat_profile","trinket_pair","individual talents"},0))),"") -> 0 | B10: =IFERROR(IF(INDEX(('Ranked Chart'!$H$6:$H$25,'Ranked Chart'!$J$6:$J$25,'Ranked Chart'!$L$6:$L$25,'Ranked Chart'!$N$6:$N$25,'Ranked Chart'!$P$6:$P$25,'Ranked Chart'!$R$6:$R$25,'Ranked Chart'!$T$6:$T$25),ROWS($A$6:A10),1,MATCH($B$1,{"Summary","talent_str","race","trinket","stat_profile","trinket_pair","individual talents"},0))>0,INDEX(('Ranked Chart'!$H$6:$H$25,'Ranked Chart'!$J$6:$J$25,'Ranked Chart'!$L$6:$L$25,'Ranked Chart'!$N$6:$N$25,'Ranked Chart'!$P$6:$P$25,'Ranked Chart'!$R$6:$R$25,'Ranked Chart'!$T$6:$T$25),ROWS($A$6:A10),1,MATCH($B$1,{"Summary","talent_str","race","trinket","stat_profile","trinket_pair","individual talents"},0)),""),"") -> 0 | C10: =IF($B10="","",$B10) -> 0 | E10: =IF($A10="","",IF($D$4>$D$3,MAX(0,MIN($C10,$D$4)-$D$3)/($D$4-$D$3),"")) -> 0 | G10: Void Elf | galactic_gladiators_badge_of_ferocity + galactic_gladiators_insignia_of_alacrity | C4DAAAAAAAAAAAAAAAAAAAAAAYGmZZmZmFmZGaGzAAAwAAAAzMzssMzEL… | H10: 0.9783065 | I10: C4DAAAAAAAAAAAAAAAAAAAAAAYGmZZmZmFmZGaGzAAAwAAAAzMzssMzELAAsNmZmZmtFLzMmlxMjxMzMsxMzMmBAYAAAgZmZWAAYGAA | J10: 0.9783065
A11: =IFERROR(IF($B11="","",INDEX(('Ranked Chart'!$G$6:$G$25,'Ranked Chart'!$I$6:$I$25,'Ranked Chart'!$K$6:$K$25,'Ranked Chart'!$M$6:$M$25,'Ranked Chart'!$O$6:$O$25,'Ranked Chart'!$Q$6:$Q$25,'Ranked Chart'!$S$6:$S$25),ROWS($A$6:A11),1,MATCH($B$1,{"Summary","talent_str","race","trinket","stat_profile","trinket_pair","individual talents"},0))),"") -> 0 | B11: =IFERROR(IF(INDEX(('Ranked Chart'!$H$6:$H$25,'Ranked Chart'!$J$6:$J$25,'Ranked Chart'!$L$6:$L$25,'Ranked Chart'!$N$6:$N$25,'Ranked Chart'!$P$6:$P$25,'Ranked Chart'!$R$6:$R$25,'Ranked Chart'!$T$6:$T$25),ROWS($A$6:A11),1,MATCH($B$1,{"Summary","talent_str","race","trinket","stat_profile","trinket_pair","individual talents"},0))>0,INDEX(('Ranked Chart'!$H$6:$H$25,'Ranked Chart'!$J$6:$J$25,'Ranked Chart'!$L$6:$L$25,'Ranked Chart'!$N$6:$N$25,'Ranked Chart'!$P$6:$P$25,'Ranked Chart'!$R$6:$R$25,'Ranked Chart'!$T$6:$T$25),ROWS($A$6:A11),1,MATCH($B$1,{"Summary","talent_str","race","trinket","stat_profile","trinket_pair","individual talents"},0)),""),"") -> 0 | C11: =IF($B11="","",$B11) -> 0 | E11: =IF($A11="","",IF($D$4>$D$3,MAX(0,MIN($C11,$D$4)-$D$3)/($D$4-$D$3),"")) -> 0 | G11: Void Elf | galactic_gladiators_badge_of_ferocity + galactic_gladiators_insignia_of_alacrity | C4DAAAAAAAAAAAAAAAAAAAAAAYGmZZmZmFmZGaGzAAAwAAAAzMzssMzEL… | H11: 0.97359945 | I11: C4DAAAAAAAAAAAAAAAAAAAAAAYGmZZmZmFmZGaGzAAAwAAAAzMzssMzELAAsxMzMzstZZmxsMzMjxMzMsxMzMmBAYAAAgZmZWAAYGAA | J11: 0.97359945
A12: =IFERROR(IF($B12="","",INDEX(('Ranked Chart'!$G$6:$G$25,'Ranked Chart'!$I$6:$I$25,'Ranked Chart'!$K$6:$K$25,'Ranked Chart'!$M$6:$M$25,'Ranked Chart'!$O$6:$O$25,'Ranked Chart'!$Q$6:$Q$25,'Ranked Chart'!$S$6:$S$25),ROWS($A$6:A12),1,MATCH($B$1,{"Summary","talent_str","race","trinket","stat_profile","trinket_pair","individual talents"},0))),"") -> 0 | B12: =IFERROR(IF(INDEX(('Ranked Chart'!$H$6:$H$25,'Ranked Chart'!$J$6:$J$25,'Ranked Chart'!$L$6:$L$25,'Ranked Chart'!$N$6:$N$25,'Ranked Chart'!$P$6:$P$25,'Ranked Chart'!$R$6:$R$25,'Ranked Chart'!$T$6:$T$25),ROWS($A$6:A12),1,MATCH($B$1,{"Summary","talent_str","race","trinket","stat_profile","trinket_pair","individual talents"},0))>0,INDEX(('Ranked Chart'!$H$6:$H$25,'Ranked Chart'!$J$6:$J$25,'Ranked Chart'!$L$6:$L$25,'Ranked Chart'!$N$6:$N$25,'Ranked Chart'!$P$6:$P$25,'Ranked Chart'!$R$6:$R$25,'Ranked Chart'!$T$6:$T$25),ROWS($A$6:A12),1,MATCH($B$1,{"Summary","talent_str","race","trinket","stat_profile","trinket_pair","individual talents"},0)),""),"") -> 0 | C12: =IF($B12="","",$B12) -> 0 | E12: =IF($A12="","",IF($D$4>$D$3,MAX(0,MIN($C12,$D$4)-$D$3)/($D$4-$D$3),"")) -> 0 | G12: Void Elf | galactic_gladiators_badge_of_ferocity + galactic_gladiators_insignia_of_alacrity | C4DAAAAAAAAAAAAAAAAAAAAAAYGmZZmZmFmZGaGzAAAwAAAAzMzssMzEL… | H12: 0.97257823 | I12: C4DAAAAAAAAAAAAAAAAAAAAAAYGmZZmZmFmZGaGzAAAwAAAAzMzssMzELAAsxMzMzstYZmxsMzMjxMzMsxMzMmBAYAAAgZmZWAAYGAA | J12: 0.97257823
A13: =IFERROR(IF($B13="","",INDEX(('Ranked Chart'!$G$6:$G$25,'Ranked Chart'!$I$6:$I$25,'Ranked Chart'!$K$6:$K$25,'Ranked Chart'!$M$6:$M$25,'Ranked Chart'!$O$6:$O$25,'Ranked Chart'!$Q$6:$Q$25,'Ranked Chart'!$S$6:$S$25),ROWS($A$6:A13),1,MATCH($B$1,{"Summary","talent_str","race","trinket","stat_profile","trinket_pair","individual talents"},0))),"") -> 0 | B13: =IFERROR(IF(INDEX(('Ranked Chart'!$H$6:$H$25,'Ranked Chart'!$J$6:$J$25,'Ranked Chart'!$L$6:$L$25,'Ranked Chart'!$N$6:$N$25,'Ranked Chart'!$P$6:$P$25,'Ranked Chart'!$R$6:$R$25,'Ranked Chart'!$T$6:$T$25),ROWS($A$6:A13),1,MATCH($B$1,{"Summary","talent_str","race","trinket","stat_profile","trinket_pair","individual talents"},0))>0,INDEX(('Ranked Chart'!$H$6:$H$25,'Ranked Chart'!$J$6:$J$25,'Ranked Chart'!$L$6:$L$25,'Ranked Chart'!$N$6:$N$25,'Ranked Chart'!$P$6:$P$25,'Ranked Chart'!$R$6:$R$25,'Ranked Chart'!$T$6:$T$25),ROWS($A$6:A13),1,MATCH($B$1,{"Summary","talent_str","race","trinket","stat_profile","trinket_pair","individual talents"},0)),""),"") -> 0 | C13: =IF($B13="","",$B13) -> 0 | E13: =IF($A13="","",IF($D$4>$D$3,MAX(0,MIN($C13,$D$4)-$D$3)/($D$4-$D$3),"")) -> 0 | G13: Void Elf | galactic_gladiators_badge_of_ferocity + galactic_gladiators_insignia_of_alacrity | C4DAAAAAAAAAAAAAAAAAAAAAAYGmZZmZmFmZGaGzAAAwAAAAzMzssMzEL… | H13: 0.97075532 | I13: C4DAAAAAAAAAAAAAAAAAAAAAAYGmZZmZmFmZGaGzAAAwAAAAzMzssMzELAAsNmZmZmtFbzMmlZmZMmZmhNmZmxAAYAAAgZmZWAAYGAA | J13: 0.97075532
A14: =IFERROR(IF($B14="","",INDEX(('Ranked Chart'!$G$6:$G$25,'Ranked Chart'!$I$6:$I$25,'Ranked Chart'!$K$6:$K$25,'Ranked Chart'!$M$6:$M$25,'Ranked Chart'!$O$6:$O$25,'Ranked Chart'!$Q$6:$Q$25,'Ranked Chart'!$S$6:$S$25),ROWS($A$6:A14),1,MATCH($B$1,{"Summary","talent_str","race","trinket","stat_profile","trinket_pair","individual talents"},0))),"") -> 0 | B14: =IFERROR(IF(INDEX(('Ranked Chart'!$H$6:$H$25,'Ranked Chart'!$J$6:$J$25,'Ranked Chart'!$L$6:$L$25,'Ranked Chart'!$N$6:$N$25,'Ranked Chart'!$P$6:$P$25,'Ranked Chart'!$R$6:$R$25,'Ranked Chart'!$T$6:$T$25),ROWS($A$6:A14),1,MATCH($B$1,{"Summary","talent_str","race","trinket","stat_profile","trinket_pair","individual talents"},0))>0,INDEX(('Ranked Chart'!$H$6:$H$25,'Ranked Chart'!$J$6:$J$25,'Ranked Chart'!$L$6:$L$25,'Ranked Chart'!$N$6:$N$25,'Ranked Chart'!$P$6:$P$25,'Ranked Chart'!$R$6:$R$25,'Ranked Chart'!$T$6:$T$25),ROWS($A$6:A14),1,MATCH($B$1,{"Summary","talent_str","race","trinket","stat_profile","trinket_pair","individual talents"},0)),""),"") -> 0 | C14: =IF($B14="","",$B14) -> 0 | E14: =IF($A14="","",IF($D$4>$D$3,MAX(0,MIN($C14,$D$4)-$D$3)/($D$4-$D$3),"")) -> 0 | G14: Void Elf | galactic_gladiators_badge_of_ferocity + galactic_gladiators_insignia_of_alacrity | C4DAAAAAAAAAAAAAAAAAAAAAAYGmZZmZmFmZGaGzAAAwAAAAzMzssMzEL… | H14: 0.97073798 | I14: C4DAAAAAAAAAAAAAAAAAAAAAAYGmZZmZmFmZGaGzAAAwAAAAzMzssMzELAAsNmZmZmtNbzMmlxMjxMzMsxMzMmBAYAAAgZmZWAAYGAA | J14: 0.97073798
A15: =IFERROR(IF($B15="","",INDEX(('Ranked Chart'!$G$6:$G$25,'Ranked Chart'!$I$6:$I$25,'Ranked Chart'!$K$6:$K$25,'Ranked Chart'!$M$6:$M$25,'Ranked Chart'!$O$6:$O$25,'Ranked Chart'!$Q$6:$Q$25,'Ranked Chart'!$S$6:$S$25),ROWS($A$6:A15),1,MATCH($B$1,{"Summary","talent_str","race","trinket","stat_profile","trinket_pair","individual talents"},0))),"") -> 0 | B15: =IFERROR(IF(INDEX(('Ranked Chart'!$H$6:$H$25,'Ranked Chart'!$J$6:$J$25,'Ranked Chart'!$L$6:$L$25,'Ranked Chart'!$N$6:$N$25,'Ranked Chart'!$P$6:$P$25,'Ranked Chart'!$R$6:$R$25,'Ranked Chart'!$T$6:$T$25),ROWS($A$6:A15),1,MATCH($B$1,{"Summary","talent_str","race","trinket","stat_profile","trinket_pair","individual talents"},0))>0,INDEX(('Ranked Chart'!$H$6:$H$25,'Ranked Chart'!$J$6:$J$25,'Ranked Chart'!$L$6:$L$25,'Ranked Chart'!$N$6:$N$25,'Ranked Chart'!$P$6:$P$25,'Ranked Chart'!$R$6:$R$25,'Ranked Chart'!$T$6:$T$25),ROWS($A$6:A15),1,MATCH($B$1,{"Summary","talent_str","race","trinket","stat_profile","trinket_pair","individual talents"},0)),""),"") -> 0 | C15: =IF($B15="","",$B15) -> 0 | E15: =IF($A15="","",IF($D$4>$D$3,MAX(0,MIN($C15,$D$4)-$D$3)/($D$4-$D$3),"")) -> 0 | G15: Void Elf | galactic_gladiators_badge_of_ferocity + galactic_gladiators_insignia_of_alacrity | C4DAAAAAAAAAAAAAAAAAAAAAAYGmZZmZmFmZGaGzAAAwAAAAzMzssMzEL… | H15: 0.96992022 | I15: C4DAAAAAAAAAAAAAAAAAAAAAAYGmZZmZmFmZGaGzAAAwAAAAzMzssMzELAAsNmZmZmtNbzMmlZmZMmZmhNmZmxAAYAAAgZmZWAAYGAA | J15: 0.96992022
A16: =IFERROR(IF($B16="","",INDEX(('Ranked Chart'!$G$6:$G$25,'Ranked Chart'!$I$6:$I$25,'Ranked Chart'!$K$6:$K$25,'Ranked Chart'!$M$6:$M$25,'Ranked Chart'!$O$6:$O$25,'Ranked Chart'!$Q$6:$Q$25,'Ranked Chart'!$S$6:$S$25),ROWS($A$6:A16),1,MATCH($B$1,{"Summary","talent_str","race","trinket","stat_profile","trinket_pair","individual talents"},0))),"") -> 0 | B16: =IFERROR(IF(INDEX(('Ranked Chart'!$H$6:$H$25,'Ranked Chart'!$J$6:$J$25,'Ranked Chart'!$L$6:$L$25,'Ranked Chart'!$N$6:$N$25,'Ranked Chart'!$P$6:$P$25,'Ranked Chart'!$R$6:$R$25,'Ranked Chart'!$T$6:$T$25),ROWS($A$6:A16),1,MATCH($B$1,{"Summary","talent_str","race","trinket","stat_profile","trinket_pair","individual talents"},0))>0,INDEX(('Ranked Chart'!$H$6:$H$25,'Ranked Chart'!$J$6:$J$25,'Ranked Chart'!$L$6:$L$25,'Ranked Chart'!$N$6:$N$25,'Ranked Chart'!$P$6:$P$25,'Ranked Chart'!$R$6:$R$25,'Ranked Chart'!$T$6:$T$25),ROWS($A$6:A16),1,MATCH($B$1,{"Summary","talent_str","race","trinket","stat_profile","trinket_pair","individual talents"},0)),""),"") -> 0 | C16: =IF($B16="","",$B16) -> 0 | E16: =IF($A16="","",IF($D$4>$D$3,MAX(0,MIN($C16,$D$4)-$D$3)/($D$4-$D$3),"")) -> 0 | G16: Void Elf | galactic_gladiators_badge_of_ferocity + galactic_gladiators_insignia_of_alacrity | C4DAAAAAAAAAAAAAAAAAAAAAAYGmZZmZmFmZGaGzAAAwAAAAzMzssMzEL… | H16: 0.96934756 | I16: C4DAAAAAAAAAAAAAAAAAAAAAAYGmZZmZmFmZGaGzAAAwAAAAzMzssMzELAAsxMzMzstYbmxsMzMjxMzMsxMzMmBAYAAAgZmZWAAYGAA | J16: 0.96934756
A17: =IFERROR(IF($B17="","",INDEX(('Ranked Chart'!$G$6:$G$25,'Ranked Chart'!$I$6:$I$25,'Ranked Chart'!$K$6:$K$25,'Ranked Chart'!$M$6:$M$25,'Ranked Chart'!$O$6:$O$25,'Ranked Chart'!$Q$6:$Q$25,'Ranked Chart'!$S$6:$S$25),ROWS($A$6:A17),1,MATCH($B$1,{"Summary","talent_str","race","trinket","stat_profile","trinket_pair","individual talents"},0))),"") -> 0 | B17: =IFERROR(IF(INDEX(('Ranked Chart'!$H$6:$H$25,'Ranked Chart'!$J$6:$J$25,'Ranked Chart'!$L$6:$L$25,'Ranked Chart'!$N$6:$N$25,'Ranked Chart'!$P$6:$P$25,'Ranked Chart'!$R$6:$R$25,'Ranked Chart'!$T$6:$T$25),ROWS($A$6:A17),1,MATCH($B$1,{"Summary","talent_str","race","trinket","stat_profile","trinket_pair","individual talents"},0))>0,INDEX(('Ranked Chart'!$H$6:$H$25,'Ranked Chart'!$J$6:$J$25,'Ranked Chart'!$L$6:$L$25,'Ranked Chart'!$N$6:$N$25,'Ranked Chart'!$P$6:$P$25,'Ranked Chart'!$R$6:$R$25,'Ranked Chart'!$T$6:$T$25),ROWS($A$6:A17),1,MATCH($B$1,{"Summary","talent_str","race","trinket","stat_profile","trinket_pair","individual talents"},0)),""),"") -> 0 | C17: =IF($B17="","",$B17) -> 0 | E17: =IF($A17="","",IF($D$4>$D$3,MAX(0,MIN($C17,$D$4)-$D$3)/($D$4-$D$3),"")) -> 0 | G17: Void Elf | galactic_gladiators_badge_of_ferocity + galactic_gladiators_insignia_of_alacrity | C4DAAAAAAAAAAAAAAAAAAAAAAYGmZZmZmFmZGaGzAAAwAAAAzMzssMzEL… | H17: 0.96901023 | I17: C4DAAAAAAAAAAAAAAAAAAAAAAYGmZZmZmFmZGaGzAAAwAAAAzMzssMzELAAsNmZmZmtFbzMmlxMjxMzMsxMzMmBAYAAAgZmZWAAYGAA | J17: 0.96901023
A18: =IFERROR(IF($B18="","",INDEX(('Ranked Chart'!$G$6:$G$25,'Ranked Chart'!$I$6:$I$25,'Ranked Chart'!$K$6:$K$25,'Ranked Chart'!$M$6:$M$25,'Ranked Chart'!$O$6:$O$25,'Ranked Chart'!$Q$6:$Q$25,'Ranked Chart'!$S$6:$S$25),ROWS($A$6:A18),1,MATCH($B$1,{"Summary","talent_str","race","trinket","stat_profile","trinket_pair","individual talents"},0))),"") -> 0 | B18: =IFERROR(IF(INDEX(('Ranked Chart'!$H$6:$H$25,'Ranked Chart'!$J$6:$J$25,'Ranked Chart'!$L$6:$L$25,'Ranked Chart'!$N$6:$N$25,'Ranked Chart'!$P$6:$P$25,'Ranked Chart'!$R$6:$R$25,'Ranked Chart'!$T$6:$T$25),ROWS($A$6:A18),1,MATCH($B$1,{"Summary","talent_str","race","trinket","stat_profile","trinket_pair","individual talents"},0))>0,INDEX(('Ranked Chart'!$H$6:$H$25,'Ranked Chart'!$J$6:$J$25,'Ranked Chart'!$L$6:$L$25,'Ranked Chart'!$N$6:$N$25,'Ranked Chart'!$P$6:$P$25,'Ranked Chart'!$R$6:$R$25,'Ranked Chart'!$T$6:$T$25),ROWS($A$6:A18),1,MATCH($B$1,{"Summary","talent_str","race","trinket","stat_profile","trinket_pair","individual talents"},0)),""),"") -> 0 | C18: =IF($B18="","",$B18) -> 0 | E18: =IF($A18="","",IF($D$4>$D$3,MAX(0,MIN($C18,$D$4)-$D$3)/($D$4-$D$3),"")) -> 0 | G18: Void Elf | galactic_gladiators_badge_of_ferocity + galactic_gladiators_insignia_of_alacrity | C4DAAAAAAAAAAAAAAAAAAAAAAYGmZZmZmFmZGaGzAAAwAAAAzMzssMzEL… | H18: 0.9642248 | I18: C4DAAAAAAAAAAAAAAAAAAAAAAYGmZZmZmFmZGaGzAAAwAAAAzMzssMzELAAsNmZmZmtFLzMmlZmZMmZmhNmZmxAAYAAAgZmZ2AAYGAA | J18: 0.9642248
A19: =IFERROR(IF($B19="","",INDEX(('Ranked Chart'!$G$6:$G$25,'Ranked Chart'!$I$6:$I$25,'Ranked Chart'!$K$6:$K$25,'Ranked Chart'!$M$6:$M$25,'Ranked Chart'!$O$6:$O$25,'Ranked Chart'!$Q$6:$Q$25,'Ranked Chart'!$S$6:$S$25),ROWS($A$6:A19),1,MATCH($B$1,{"Summary","talent_str","race","trinket","stat_profile","trinket_pair","individual talents"},0))),"") -> 0 | B19: =IFERROR(IF(INDEX(('Ranked Chart'!$H$6:$H$25,'Ranked Chart'!$J$6:$J$25,'Ranked Chart'!$L$6:$L$25,'Ranked Chart'!$N$6:$N$25,'Ranked Chart'!$P$6:$P$25,'Ranked Chart'!$R$6:$R$25,'Ranked Chart'!$T$6:$T$25),ROWS($A$6:A19),1,MATCH($B$1,{"Summary","talent_str","race","trinket","stat_profile","trinket_pair","individual talents"},0))>0,INDEX(('Ranked Chart'!$H$6:$H$25,'Ranked Chart'!$J$6:$J$25,'Ranked Chart'!$L$6:$L$25,'Ranked Chart'!$N$6:$N$25,'Ranked Chart'!$P$6:$P$25,'Ranked Chart'!$R$6:$R$25,'Ranked Chart'!$T$6:$T$25),ROWS($A$6:A19),1,MATCH($B$1,{"Summary","talent_str","race","trinket","stat_profile","trinket_pair","individual talents"},0)),""),"") -> 0 | C19: =IF($B19="","",$B19) -> 0 | E19: =IF($A19="","",IF($D$4>$D$3,MAX(0,MIN($C19,$D$4)-$D$3)/($D$4-$D$3),"")) -> 0 | G19: Void Elf | galactic_gladiators_badge_of_ferocity + galactic_gladiators_insignia_of_alacrity | C4DAAAAAAAAAAAAAAAAAAAAAAYGmZZmZmFmZGaGzAAAwAAAAzMzssMzEL… | H19: 0.96288819 | I19: C4DAAAAAAAAAAAAAAAAAAAAAAYGmZZmZmFmZGaGzAAAwAAAAzMzssMzELAAsNmZmZmtNLzMmlxMjxMzMsxMzMmBAYAAAgZmZ2AAYGAA | J19: 0.96288819
... A25: =IFERROR(IF($B25="","",INDEX(('Ranked Chart'!$G$6:$G$25,'Ranked Chart'!$I$6:$I$25,'Ranked Chart'!$K$6:$K$25,'Ranked Chart'!$M$6:$M$25,'Ranked Chart'!$O$6:$O$25,'Ranked Chart'!$Q$6:$Q$25,'Ranked Chart'!$S$6:$S$25),ROWS($A$6:A25),1,MATCH($B$1,{"Summary","talent_str","race","trinket","stat_profile","trinket_pair","individual talents"},0))),"") -> 0 | B25: =IFERROR(IF(INDEX(('Ranked Chart'!$H$6:$H$25,'Ranked Chart'!$J$6:$J$25,'Ranked Chart'!$L$6:$L$25,'Ranked Chart'!$N$6:$N$25,'Ranked Chart'!$P$6:$P$25,'Ranked Chart'!$R$6:$R$25,'Ranked Chart'!$T$6:$T$25),ROWS($A$6:A25),1,MATCH($B$1,{"Summary","talent_str","race","trinket","stat_profile","trinket_pair","individual talents"},0))>0,INDEX(('Ranked Chart'!$H$6:$H$25,'Ranked Chart'!$J$6:$J$25,'Ranked Chart'!$L$6:$L$25,'Ranked Chart'!$N$6:$N$25,'Ranked Chart'!$P$6:$P$25,'Ranked Chart'!$R$6:$R$25,'Ranked Chart'!$T$6:$T$25),ROWS($A$6:A25),1,MATCH($B$1,{"Summary","talent_str","race","trinket","stat_profile","trinket_pair","individual talents"},0)),""),"") -> 0 | C25: =IF($B25="","",$B25) -> 0 | E25: =IF($A25="","",IF($D$4>$D$3,MAX(0,MIN($C25,$D$4)-$D$3)/($D$4-$D$3),"")) -> 0 | G25: Void Elf | galactic_gladiators_badge_of_ferocity + galactic_gladiators_insignia_of_alacrity | C4DAAAAAAAAAAAAAAAAAAAAAAYGmZZmZmFmZGaGzAAAwAAAAzMzssMzEL… | H25: 0.95527648 | I25: C4DAAAAAAAAAAAAAAAAAAAAAAYGmZZmZmFmZGaGzAAAwAAAAzMzssMzELAAsxMzMzssYZmxsMzMjxMzMsxMzMmBAYAAAgZmZWAAYGAA | J25: 0.95527648

Sheet Stat Heatmap
